2015-04-17 23:24:27,441 INFO org.apache.hadoop.yarn.server.resourcemanager.ResourceManager: STARTUP_MSG: 
/************************************************************
STARTUP_MSG: Starting ResourceManager
STARTUP_MSG:   host = k05n26/10.111.5.26
STARTUP_MSG:   args = []
STARTUP_MSG:   version = 2.5.1
STARTUP_MSG:   build = https://git-wip-us.apache.org/repos/asf/hadoop.git -r 2e18d179e4a8065b6a9f29cf2de9451891265cce; compiled by 'jenkins' on 2014-09-05T23:11Z
STARTUP_MSG:   java = 1.6.0_22
************************************************************/
2015-04-17 23:24:27,448 INFO org.apache.hadoop.yarn.server.resourcemanager.ResourceManager: registered UNIX signal handlers for [TERM, HUP, INT]
2015-04-17 23:24:27,612 INFO org.apache.hadoop.conf.Configuration: found resource core-site.xml at file:/gpfs/courses/cse587/spring2015/students/u2/hw4/Uploader/hw4/config-3719024/core-site.xml
2015-04-17 23:24:27,702 WARN org.apache.hadoop.util.NativeCodeLoader: Unable to load native-hadoop library for your platform... using builtin-java classes where applicable
2015-04-17 23:24:27,703 INFO org.apache.hadoop.security.Groups: clearing userToGroupsMap cache
2015-04-17 23:24:27,709 INFO org.apache.hadoop.conf.Configuration: found resource yarn-site.xml at file:/gpfs/courses/cse587/spring2015/students/u2/hw4/Uploader/hw4/config-3719024/yarn-site.xml
2015-04-17 23:24:27,755 WARN org.apache.hadoop.conf.Configuration: java.io.BufferedInputStream@1055e55f:an attempt to override final parameter: yarn.resourcemanager.hostname;  Ignoring.
2015-04-17 23:24:27,758 INFO org.apache.hadoop.yarn.event.AsyncDispatcher: Registering class org.apache.hadoop.yarn.server.resourcemanager.RMFatalEventType for class org.apache.hadoop.yarn.server.resourcemanager.ResourceManager$RMFatalEventDispatcher
2015-04-17 23:24:28,086 INFO org.apache.hadoop.yarn.server.resourcemanager.security.NMTokenSecretManagerInRM: NMTokenKeyRollingInterval: 86400000ms and NMTokenKeyActivationDelay: 900000ms
2015-04-17 23:24:28,089 INFO org.apache.hadoop.yarn.server.resourcemanager.security.RMContainerTokenSecretManager: ContainerTokenKeyRollingInterval: 86400000ms and ContainerTokenKeyActivationDelay: 900000ms
2015-04-17 23:24:28,092 INFO org.apache.hadoop.yarn.server.resourcemanager.security.AMRMTokenSecretManager: Rolling master-key for amrm-tokens
2015-04-17 23:24:28,110 INFO org.apache.hadoop.yarn.event.AsyncDispatcher: Registering class org.apache.hadoop.yarn.server.resourcemanager.recovery.RMStateStoreEventType for class org.apache.hadoop.yarn.server.resourcemanager.recovery.RMStateStore$ForwardingEventHandler
2015-04-17 23:24:28,242 INFO org.apache.hadoop.yarn.event.AsyncDispatcher: Registering class org.apache.hadoop.yarn.server.resourcemanager.NodesListManagerEventType for class org.apache.hadoop.yarn.server.resourcemanager.NodesListManager
2015-04-17 23:24:28,242 INFO org.apache.hadoop.yarn.server.resourcemanager.ResourceManager: Using Scheduler: org.apache.hadoop.yarn.server.resourcemanager.scheduler.capacity.CapacityScheduler
2015-04-17 23:24:28,269 INFO org.apache.hadoop.yarn.event.AsyncDispatcher: Registering class org.apache.hadoop.yarn.server.resourcemanager.scheduler.event.SchedulerEventType for class org.apache.hadoop.yarn.server.resourcemanager.ResourceManager$SchedulerEventDispatcher
2015-04-17 23:24:28,270 INFO org.apache.hadoop.yarn.event.AsyncDispatcher: Registering class org.apache.hadoop.yarn.server.resourcemanager.rmapp.RMAppEventType for class org.apache.hadoop.yarn.server.resourcemanager.ResourceManager$ApplicationEventDispatcher
2015-04-17 23:24:28,271 INFO org.apache.hadoop.yarn.event.AsyncDispatcher: Registering class org.apache.hadoop.yarn.server.resourcemanager.rmapp.attempt.RMAppAttemptEventType for class org.apache.hadoop.yarn.server.resourcemanager.ResourceManager$ApplicationAttemptEventDispatcher
2015-04-17 23:24:28,272 INFO org.apache.hadoop.yarn.event.AsyncDispatcher: Registering class org.apache.hadoop.yarn.server.resourcemanager.rmnode.RMNodeEventType for class org.apache.hadoop.yarn.server.resourcemanager.ResourceManager$NodeEventDispatcher
2015-04-17 23:24:28,333 INFO org.apache.hadoop.metrics2.impl.MetricsConfig: loaded properties from hadoop-metrics2.properties
2015-04-17 23:24:28,375 INFO org.apache.hadoop.metrics2.impl.MetricsSystemImpl: Scheduled snapshot period at 10 second(s).
2015-04-17 23:24:28,375 INFO org.apache.hadoop.metrics2.impl.MetricsSystemImpl: ResourceManager metrics system started
2015-04-17 23:24:28,416 INFO org.apache.hadoop.yarn.event.AsyncDispatcher: Registering class org.apache.hadoop.yarn.server.resourcemanager.RMAppManagerEventType for class org.apache.hadoop.yarn.server.resourcemanager.RMAppManager
2015-04-17 23:24:28,423 INFO org.apache.hadoop.yarn.event.AsyncDispatcher: Registering class org.apache.hadoop.yarn.server.resourcemanager.amlauncher.AMLauncherEventType for class org.apache.hadoop.yarn.server.resourcemanager.amlauncher.ApplicationMasterLauncher
2015-04-17 23:24:28,425 INFO org.apache.hadoop.yarn.server.resourcemanager.RMNMInfo: Registered RMNMInfo MBean
2015-04-17 23:24:28,427 INFO org.apache.hadoop.yarn.event.AsyncDispatcher: Registering class org.apache.hadoop.yarn.server.resourcemanager.ahs.WritingHistoryEventType for class org.apache.hadoop.yarn.server.resourcemanager.ahs.RMApplicationHistoryWriter$ForwardingEventHandler
2015-04-17 23:24:28,427 INFO org.apache.hadoop.yarn.event.AsyncDispatcher: Registering class org.apache.hadoop.yarn.server.resourcemanager.ahs.WritingHistoryEventType for class org.apache.hadoop.yarn.server.resourcemanager.ahs.RMApplicationHistoryWriter$ForwardingEventHandler
2015-04-17 23:24:28,427 INFO org.apache.hadoop.yarn.event.AsyncDispatcher: Registering class org.apache.hadoop.yarn.server.resourcemanager.ahs.WritingHistoryEventType for class org.apache.hadoop.yarn.server.resourcemanager.ahs.RMApplicationHistoryWriter$ForwardingEventHandler
2015-04-17 23:24:28,427 INFO org.apache.hadoop.yarn.event.AsyncDispatcher: Registering class org.apache.hadoop.yarn.server.resourcemanager.ahs.WritingHistoryEventType for class org.apache.hadoop.yarn.server.resourcemanager.ahs.RMApplicationHistoryWriter$ForwardingEventHandler
2015-04-17 23:24:28,427 INFO org.apache.hadoop.yarn.event.AsyncDispatcher: Registering class org.apache.hadoop.yarn.server.resourcemanager.ahs.WritingHistoryEventType for class org.apache.hadoop.yarn.server.resourcemanager.ahs.RMApplicationHistoryWriter$ForwardingEventHandler
2015-04-17 23:24:28,427 INFO org.apache.hadoop.yarn.event.AsyncDispatcher: Registering class org.apache.hadoop.yarn.server.resourcemanager.ahs.WritingHistoryEventType for class org.apache.hadoop.yarn.server.resourcemanager.ahs.RMApplicationHistoryWriter$ForwardingEventHandler
2015-04-17 23:24:28,427 INFO org.apache.hadoop.yarn.event.AsyncDispatcher: Registering class org.apache.hadoop.yarn.server.resourcemanager.ahs.WritingHistoryEventType for class org.apache.hadoop.yarn.server.resourcemanager.ahs.RMApplicationHistoryWriter$ForwardingEventHandler
2015-04-17 23:24:28,427 INFO org.apache.hadoop.yarn.event.AsyncDispatcher: Registering class org.apache.hadoop.yarn.server.resourcemanager.ahs.WritingHistoryEventType for class org.apache.hadoop.yarn.server.resourcemanager.ahs.RMApplicationHistoryWriter$ForwardingEventHandler
2015-04-17 23:24:28,427 INFO org.apache.hadoop.yarn.event.AsyncDispatcher: Registering class org.apache.hadoop.yarn.server.resourcemanager.ahs.WritingHistoryEventType for class org.apache.hadoop.yarn.server.resourcemanager.ahs.RMApplicationHistoryWriter$ForwardingEventHandler
2015-04-17 23:24:28,427 INFO org.apache.hadoop.yarn.event.AsyncDispatcher: Registering class org.apache.hadoop.yarn.server.resourcemanager.ahs.WritingHistoryEventType for class org.apache.hadoop.yarn.server.resourcemanager.ahs.RMApplicationHistoryWriter$ForwardingEventHandler
2015-04-17 23:24:28,428 INFO org.apache.hadoop.util.HostsFileReader: Refreshing hosts (include/exclude) list
2015-04-17 23:24:28,430 INFO org.apache.hadoop.conf.Configuration: found resource capacity-scheduler.xml at file:/gpfs/courses/cse587/spring2015/students/u2/hw4/Uploader/hw4/config-3719024/capacity-scheduler.xml
2015-04-17 23:24:28,470 INFO org.apache.hadoop.yarn.server.resourcemanager.scheduler.capacity.ParentQueue: root, capacity=1.0, asboluteCapacity=1.0, maxCapacity=1.0, asboluteMaxCapacity=1.0, state=RUNNING, acls=ADMINISTER_QUEUE:*SUBMIT_APPLICATIONS:*
2015-04-17 23:24:28,471 INFO org.apache.hadoop.yarn.server.resourcemanager.scheduler.capacity.ParentQueue: Initialized parent-queue root name=root, fullname=root
2015-04-17 23:24:28,478 INFO org.apache.hadoop.yarn.server.resourcemanager.scheduler.capacity.LeafQueue: Initializing default
capacity = 1.0 [= (float) configuredCapacity / 100 ]
asboluteCapacity = 1.0 [= parentAbsoluteCapacity * capacity ]
maxCapacity = 1.0 [= configuredMaxCapacity ]
absoluteMaxCapacity = 1.0 [= 1.0 maximumCapacity undefined, (parentAbsoluteMaxCapacity * maximumCapacity) / 100 otherwise ]
userLimit = 100 [= configuredUserLimit ]
userLimitFactor = 1.0 [= configuredUserLimitFactor ]
maxApplications = 10000 [= configuredMaximumSystemApplicationsPerQueue or (int)(configuredMaximumSystemApplications * absoluteCapacity)]
maxApplicationsPerUser = 10000 [= (int)(maxApplications * (userLimit / 100.0f) * userLimitFactor) ]
maxActiveApplications = 1 [= max((int)ceil((clusterResourceMemory / minimumAllocation) * maxAMResourcePerQueuePercent * absoluteMaxCapacity),1) ]
maxActiveAppsUsingAbsCap = 1 [= max((int)ceil((clusterResourceMemory / minimumAllocation) *maxAMResourcePercent * absoluteCapacity),1) ]
maxActiveApplicationsPerUser = 1 [= max((int)(maxActiveApplications * (userLimit / 100.0f) * userLimitFactor),1) ]
usedCapacity = 0.0 [= usedResourcesMemory / (clusterResourceMemory * absoluteCapacity)]
absoluteUsedCapacity = 0.0 [= usedResourcesMemory / clusterResourceMemory]
maxAMResourcePerQueuePercent = 0.1 [= configuredMaximumAMResourcePercent ]
minimumAllocationFactor = 0.875 [= (float)(maximumAllocationMemory - minimumAllocationMemory) / maximumAllocationMemory ]
numContainers = 0 [= currentNumContainers ]
state = RUNNING [= configuredState ]
acls = ADMINISTER_QUEUE:*SUBMIT_APPLICATIONS:* [= configuredAcls ]
nodeLocalityDelay = 40

2015-04-17 23:24:28,478 INFO org.apache.hadoop.yarn.server.resourcemanager.scheduler.capacity.CapacityScheduler: Initialized queue: default: capacity=1.0, absoluteCapacity=1.0, usedResources=<memory:0, vCores:0>, usedCapacity=0.0, absoluteUsedCapacity=0.0, numApps=0, numContainers=0
2015-04-17 23:24:28,478 INFO org.apache.hadoop.yarn.server.resourcemanager.scheduler.capacity.CapacityScheduler: Initialized queue: root: numChildQueue= 1, capacity=1.0, absoluteCapacity=1.0, usedResources=<memory:0, vCores:0>usedCapacity=0.0, numApps=0, numContainers=0
2015-04-17 23:24:28,478 INFO org.apache.hadoop.yarn.server.resourcemanager.scheduler.capacity.CapacityScheduler: Initialized root queue root: numChildQueue= 1, capacity=1.0, absoluteCapacity=1.0, usedResources=<memory:0, vCores:0>usedCapacity=0.0, numApps=0, numContainers=0
2015-04-17 23:24:28,478 INFO org.apache.hadoop.yarn.server.resourcemanager.scheduler.capacity.CapacityScheduler: Initialized CapacityScheduler with calculator=class org.apache.hadoop.yarn.util.resource.DefaultResourceCalculator, minimumAllocation=<<memory:1024, vCores:1>>, maximumAllocation=<<memory:8192, vCores:32>>, asynchronousScheduling=false, asyncScheduleInterval=5ms
2015-04-17 23:24:28,483 INFO org.apache.hadoop.yarn.server.resourcemanager.ResourceManager: Transitioning to active state
2015-04-17 23:24:28,487 INFO org.apache.hadoop.yarn.server.resourcemanager.security.RMContainerTokenSecretManager: Rolling master-key for container-tokens
2015-04-17 23:24:28,487 INFO org.apache.hadoop.yarn.server.resourcemanager.security.AMRMTokenSecretManager: Rolling master-key for amrm-tokens
2015-04-17 23:24:28,489 INFO org.apache.hadoop.yarn.server.resourcemanager.security.NMTokenSecretManagerInRM: Rolling master-key for nm-tokens
2015-04-17 23:24:28,489 INFO org.apache.hadoop.security.token.delegation.AbstractDelegationTokenSecretManager: Updating the current master key for generating delegation tokens
2015-04-17 23:24:28,490 INFO org.apache.hadoop.yarn.server.resourcemanager.security.RMDelegationTokenSecretManager: storing master key with keyID 1
2015-04-17 23:24:28,491 INFO org.apache.hadoop.security.token.delegation.AbstractDelegationTokenSecretManager: Starting expired delegation token remover thread, tokenRemoverScanInterval=60 min(s)
2015-04-17 23:24:28,491 INFO org.apache.hadoop.security.token.delegation.AbstractDelegationTokenSecretManager: Updating the current master key for generating delegation tokens
2015-04-17 23:24:28,491 INFO org.apache.hadoop.yarn.server.resourcemanager.security.RMDelegationTokenSecretManager: storing master key with keyID 2
2015-04-17 23:24:28,515 INFO org.apache.hadoop.ipc.CallQueueManager: Using callQueue class java.util.concurrent.LinkedBlockingQueue
2015-04-17 23:24:28,529 INFO org.apache.hadoop.ipc.Server: Starting Socket Reader #1 for port 8031
2015-04-17 23:24:28,543 INFO org.apache.hadoop.yarn.factories.impl.pb.RpcServerFactoryPBImpl: Adding protocol org.apache.hadoop.yarn.server.api.ResourceTrackerPB to the server
2015-04-17 23:24:28,544 INFO org.apache.hadoop.ipc.Server: IPC Server Responder: starting
2015-04-17 23:24:28,544 INFO org.apache.hadoop.ipc.Server: IPC Server listener on 8031: starting
2015-04-17 23:24:28,577 INFO org.apache.hadoop.ipc.CallQueueManager: Using callQueue class java.util.concurrent.LinkedBlockingQueue
2015-04-17 23:24:28,582 INFO org.apache.hadoop.ipc.Server: Starting Socket Reader #1 for port 8030
2015-04-17 23:24:28,589 INFO org.apache.hadoop.yarn.factories.impl.pb.RpcServerFactoryPBImpl: Adding protocol org.apache.hadoop.yarn.api.ApplicationMasterProtocolPB to the server
2015-04-17 23:24:28,590 INFO org.apache.hadoop.ipc.Server: IPC Server Responder: starting
2015-04-17 23:24:28,590 INFO org.apache.hadoop.ipc.Server: IPC Server listener on 8030: starting
2015-04-17 23:24:28,627 INFO org.apache.hadoop.ipc.CallQueueManager: Using callQueue class java.util.concurrent.LinkedBlockingQueue
2015-04-17 23:24:28,627 INFO org.apache.hadoop.ipc.Server: Starting Socket Reader #1 for port 8032
2015-04-17 23:24:28,629 INFO org.apache.hadoop.yarn.factories.impl.pb.RpcServerFactoryPBImpl: Adding protocol org.apache.hadoop.yarn.api.ApplicationClientProtocolPB to the server
2015-04-17 23:24:28,630 INFO org.apache.hadoop.ipc.Server: IPC Server Responder: starting
2015-04-17 23:24:28,630 INFO org.apache.hadoop.ipc.Server: IPC Server listener on 8032: starting
2015-04-17 23:24:28,635 INFO org.apache.hadoop.yarn.server.resourcemanager.ResourceManager: Transitioned to active state
2015-04-17 23:24:28,689 INFO org.mortbay.log: Logging to org.slf4j.impl.Log4jLoggerAdapter(org.mortbay.log) via org.mortbay.log.Slf4jLog
2015-04-17 23:24:28,692 INFO org.apache.hadoop.http.HttpRequestLog: Http request log for http.requests.resourcemanager is not defined
2015-04-17 23:24:28,700 INFO org.apache.hadoop.http.HttpServer2: Added global filter 'safety' (class=org.apache.hadoop.http.HttpServer2$QuotingInputFilter)
2015-04-17 23:24:28,706 INFO org.apache.hadoop.http.HttpServer2: Added filter YARNAuthenticationFilter (class=org.apache.hadoop.yarn.server.security.http.RMAuthenticationFilter) to context cluster
2015-04-17 23:24:28,706 INFO org.apache.hadoop.http.HttpServer2: Added filter YARNAuthenticationFilter (class=org.apache.hadoop.yarn.server.security.http.RMAuthenticationFilter) to context static
2015-04-17 23:24:28,706 INFO org.apache.hadoop.http.HttpServer2: Added filter YARNAuthenticationFilter (class=org.apache.hadoop.yarn.server.security.http.RMAuthenticationFilter) to context logs
2015-04-17 23:24:28,707 INFO org.apache.hadoop.http.HttpServer2: Added filter static_user_filter (class=org.apache.hadoop.http.lib.StaticUserWebFilter$StaticUserFilter) to context cluster
2015-04-17 23:24:28,707 INFO org.apache.hadoop.http.HttpServer2: Added filter static_user_filter (class=org.apache.hadoop.http.lib.StaticUserWebFilter$StaticUserFilter) to context static
2015-04-17 23:24:28,707 INFO org.apache.hadoop.http.HttpServer2: Added filter static_user_filter (class=org.apache.hadoop.http.lib.StaticUserWebFilter$StaticUserFilter) to context logs
2015-04-17 23:24:28,709 INFO org.apache.hadoop.http.HttpServer2: adding path spec: /cluster/*
2015-04-17 23:24:28,710 INFO org.apache.hadoop.http.HttpServer2: adding path spec: /ws/*
2015-04-17 23:24:28,718 INFO org.apache.hadoop.http.HttpServer2: Jetty bound to port 8088
2015-04-17 23:24:28,718 INFO org.mortbay.log: jetty-6.1.26
2015-04-17 23:24:28,738 WARN org.mortbay.log: Can't reuse /tmp/Jetty_k05n26_8088_cluster____.dlymgg, using /tmp/Jetty_k05n26_8088_cluster____.dlymgg_5028980162343242237
2015-04-17 23:24:28,739 INFO org.mortbay.log: Extract jar:file:/gpfs/util/academic/hadoop/2.5.1/hadoop-2.5.1/share/hadoop/yarn/hadoop-yarn-common-2.5.1.jar!/webapps/cluster to /tmp/Jetty_k05n26_8088_cluster____.dlymgg_5028980162343242237/webapp
2015-04-17 23:24:28,885 WARN org.apache.hadoop.security.authentication.server.AuthenticationFilter: 'signature.secret' configuration not set, using a random value as secret
2015-04-17 23:24:28,907 WARN org.apache.hadoop.security.authentication.server.AuthenticationFilter: 'signature.secret' configuration not set, using a random value as secret
2015-04-17 23:24:28,908 WARN org.apache.hadoop.security.authentication.server.AuthenticationFilter: 'signature.secret' configuration not set, using a random value as secret
2015-04-17 23:24:28,911 INFO org.mortbay.log: Started HttpServer2$SelectChannelConnectorWithSafeStartup@k05n26:8088
2015-04-17 23:24:28,912 INFO org.apache.hadoop.yarn.webapp.WebApps: Web app /cluster started at 8088
2015-04-17 23:24:29,207 INFO org.apache.hadoop.yarn.webapp.WebApps: Registered webapp guice modules
2015-04-17 23:24:29,224 INFO org.apache.hadoop.ipc.CallQueueManager: Using callQueue class java.util.concurrent.LinkedBlockingQueue
2015-04-17 23:24:29,224 INFO org.apache.hadoop.ipc.Server: Starting Socket Reader #1 for port 8033
2015-04-17 23:24:29,226 INFO org.apache.hadoop.yarn.factories.impl.pb.RpcServerFactoryPBImpl: Adding protocol org.apache.hadoop.yarn.server.api.ResourceManagerAdministrationProtocolPB to the server
2015-04-17 23:24:29,226 INFO org.apache.hadoop.ipc.Server: IPC Server Responder: starting
2015-04-17 23:24:29,226 INFO org.apache.hadoop.ipc.Server: IPC Server listener on 8033: starting
2015-04-17 23:24:31,415 INFO org.apache.hadoop.yarn.util.RackResolver: Resolved k05n26.ccr.buffalo.edu to /default-rack
2015-04-17 23:24:31,421 INFO org.apache.hadoop.yarn.server.resourcemanager.ResourceTrackerService: NodeManager from node k05n26.ccr.buffalo.edu(cmPort: 33870 httpPort: 8042) registered with capability: <memory:8192, vCores:8>, assigned nodeId k05n26.ccr.buffalo.edu:33870
2015-04-17 23:24:31,423 INFO org.apache.hadoop.yarn.server.resourcemanager.rmnode.RMNodeImpl: k05n26.ccr.buffalo.edu:33870 Node Transitioned from NEW to RUNNING
2015-04-17 23:24:31,425 INFO org.apache.hadoop.yarn.server.resourcemanager.scheduler.capacity.CapacityScheduler: Added node k05n26.ccr.buffalo.edu:33870 clusterResource: <memory:8192, vCores:8>
2015-04-17 23:24:45,593 INFO org.apache.hadoop.yarn.server.resourcemanager.ClientRMService: Allocated new applicationId: 1
2015-04-17 23:24:46,594 INFO org.apache.hadoop.yarn.server.resourcemanager.ClientRMService: Application with id 1 submitted by user u2
2015-04-17 23:24:46,595 INFO org.apache.hadoop.yarn.server.resourcemanager.rmapp.RMAppImpl: Storing application with id application_1429327468486_0001
2015-04-17 23:24:46,596 INFO org.apache.hadoop.yarn.server.resourcemanager.rmapp.RMAppImpl: application_1429327468486_0001 State change from NEW to NEW_SAVING
2015-04-17 23:24:46,596 INFO org.apache.hadoop.yarn.server.resourcemanager.RMAuditLogger: USER=u2	IP=10.111.5.26	OPERATION=Submit Application Request	TARGET=ClientRMService	RESULT=SUCCESS	APPID=application_1429327468486_0001
2015-04-17 23:24:46,604 INFO org.apache.hadoop.yarn.server.resourcemanager.recovery.RMStateStore: Storing info for app: application_1429327468486_0001
2015-04-17 23:24:46,605 INFO org.apache.hadoop.yarn.server.resourcemanager.rmapp.RMAppImpl: application_1429327468486_0001 State change from NEW_SAVING to SUBMITTED
2015-04-17 23:24:46,606 INFO org.apache.hadoop.yarn.server.resourcemanager.scheduler.capacity.ParentQueue: Application added - appId: application_1429327468486_0001 user: u2 leaf-queue of parent: root #applications: 1
2015-04-17 23:24:46,607 INFO org.apache.hadoop.yarn.server.resourcemanager.scheduler.capacity.CapacityScheduler: Accepted application application_1429327468486_0001 from user: u2, in queue: default
2015-04-17 23:24:46,613 INFO org.apache.hadoop.yarn.server.resourcemanager.rmapp.RMAppImpl: application_1429327468486_0001 State change from SUBMITTED to ACCEPTED
2015-04-17 23:24:46,613 INFO org.apache.hadoop.yarn.server.resourcemanager.ApplicationMasterService: Registering app attempt : appattempt_1429327468486_0001_000001
2015-04-17 23:24:46,619 INFO org.apache.hadoop.yarn.server.resourcemanager.rmapp.attempt.RMAppAttemptImpl: appattempt_1429327468486_0001_000001 State change from NEW to SUBMITTED
2015-04-17 23:24:46,637 INFO org.apache.hadoop.yarn.server.resourcemanager.scheduler.capacity.LeafQueue: Application application_1429327468486_0001 from user: u2 activated in queue: default
2015-04-17 23:24:46,637 INFO org.apache.hadoop.yarn.server.resourcemanager.scheduler.capacity.LeafQueue: Application added - appId: application_1429327468486_0001 user: org.apache.hadoop.yarn.server.resourcemanager.scheduler.capacity.LeafQueue$User@4599d5b, leaf-queue: default #user-pending-applications: 0 #user-active-applications: 1 #queue-pending-applications: 0 #queue-active-applications: 1
2015-04-17 23:24:46,637 INFO org.apache.hadoop.yarn.server.resourcemanager.scheduler.capacity.CapacityScheduler: Added Application Attempt appattempt_1429327468486_0001_000001 to scheduler from user u2 in queue default
2015-04-17 23:24:46,639 INFO org.apache.hadoop.yarn.server.resourcemanager.rmapp.attempt.RMAppAttemptImpl: appattempt_1429327468486_0001_000001 State change from SUBMITTED to SCHEDULED
2015-04-17 23:24:47,518 INFO org.apache.hadoop.yarn.server.resourcemanager.rmcontainer.RMContainerImpl: container_1429327468486_0001_01_000001 Container Transitioned from NEW to ALLOCATED
2015-04-17 23:24:47,518 INFO org.apache.hadoop.yarn.server.resourcemanager.RMAuditLogger: USER=u2	OPERATION=AM Allocated Container	TARGET=SchedulerApp	RESULT=SUCCESS	APPID=application_1429327468486_0001	CONTAINERID=container_1429327468486_0001_01_000001
2015-04-17 23:24:47,519 INFO org.apache.hadoop.yarn.server.resourcemanager.scheduler.SchedulerNode: Assigned container container_1429327468486_0001_01_000001 of capacity <memory:2048, vCores:1> on host k05n26.ccr.buffalo.edu:33870, which has 1 containers, <memory:2048, vCores:1> used and <memory:6144, vCores:7> available after allocation
2015-04-17 23:24:47,519 INFO org.apache.hadoop.yarn.server.resourcemanager.scheduler.capacity.LeafQueue: assignedContainer application attempt=appattempt_1429327468486_0001_000001 container=Container: [ContainerId: container_1429327468486_0001_01_000001, NodeId: k05n26.ccr.buffalo.edu:33870, NodeHttpAddress: k05n26.ccr.buffalo.edu:8042, Resource: <memory:2048, vCores:1>, Priority: 0, Token: null, ] queue=default: capacity=1.0, absoluteCapacity=1.0, usedResources=<memory:0, vCores:0>, usedCapacity=0.0, absoluteUsedCapacity=0.0, numApps=1, numContainers=0 clusterResource=<memory:8192, vCores:8>
2015-04-17 23:24:47,519 INFO org.apache.hadoop.yarn.server.resourcemanager.scheduler.capacity.ParentQueue: Re-sorting assigned queue: root.default stats: default: capacity=1.0, absoluteCapacity=1.0, usedResources=<memory:2048, vCores:1>, usedCapacity=0.25, absoluteUsedCapacity=0.25, numApps=1, numContainers=1
2015-04-17 23:24:47,519 INFO org.apache.hadoop.yarn.server.resourcemanager.scheduler.capacity.ParentQueue: assignedContainer queue=root usedCapacity=0.25 absoluteUsedCapacity=0.25 used=<memory:2048, vCores:1> cluster=<memory:8192, vCores:8>
2015-04-17 23:24:47,522 INFO org.apache.hadoop.yarn.server.resourcemanager.security.NMTokenSecretManagerInRM: Sending NMToken for nodeId : k05n26.ccr.buffalo.edu:33870 for container : container_1429327468486_0001_01_000001
2015-04-17 23:24:47,525 INFO org.apache.hadoop.yarn.server.resourcemanager.rmcontainer.RMContainerImpl: container_1429327468486_0001_01_000001 Container Transitioned from ALLOCATED to ACQUIRED
2015-04-17 23:24:47,526 INFO org.apache.hadoop.yarn.server.resourcemanager.security.NMTokenSecretManagerInRM: Clear node set for appattempt_1429327468486_0001_000001
2015-04-17 23:24:47,528 INFO org.apache.hadoop.yarn.server.resourcemanager.rmapp.attempt.RMAppAttemptImpl: Storing attempt: AppId: application_1429327468486_0001 AttemptId: appattempt_1429327468486_0001_000001 MasterContainer: Container: [ContainerId: container_1429327468486_0001_01_000001, NodeId: k05n26.ccr.buffalo.edu:33870, NodeHttpAddress: k05n26.ccr.buffalo.edu:8042, Resource: <memory:2048, vCores:1>, Priority: 0, Token: Token { kind: ContainerToken, service: 10.111.5.26:33870 }, ]
2015-04-17 23:24:47,530 INFO org.apache.hadoop.yarn.server.resourcemanager.rmapp.attempt.RMAppAttemptImpl: appattempt_1429327468486_0001_000001 State change from SCHEDULED to ALLOCATED_SAVING
2015-04-17 23:24:47,538 INFO org.apache.hadoop.yarn.server.resourcemanager.rmapp.attempt.RMAppAttemptImpl: appattempt_1429327468486_0001_000001 State change from ALLOCATED_SAVING to ALLOCATED
2015-04-17 23:24:47,541 INFO org.apache.hadoop.yarn.server.resourcemanager.amlauncher.AMLauncher: Launching masterappattempt_1429327468486_0001_000001
2015-04-17 23:24:47,567 INFO org.apache.hadoop.yarn.server.resourcemanager.amlauncher.AMLauncher: Setting up container Container: [ContainerId: container_1429327468486_0001_01_000001, NodeId: k05n26.ccr.buffalo.edu:33870, NodeHttpAddress: k05n26.ccr.buffalo.edu:8042, Resource: <memory:2048, vCores:1>, Priority: 0, Token: Token { kind: ContainerToken, service: 10.111.5.26:33870 }, ] for AM appattempt_1429327468486_0001_000001
2015-04-17 23:24:47,567 INFO org.apache.hadoop.yarn.server.resourcemanager.amlauncher.AMLauncher: Command to launch container container_1429327468486_0001_01_000001 : $JAVA_HOME/bin/java -Dlog4j.configuration=container-log4j.properties -Dyarn.app.container.log.dir=<LOG_DIR> -Dyarn.app.container.log.filesize=0 -Dhadoop.root.logger=INFO,CLA  -Xmx1024m org.apache.hadoop.mapreduce.v2.app.MRAppMaster 1><LOG_DIR>/stdout 2><LOG_DIR>/stderr 
2015-04-17 23:24:47,797 INFO org.apache.hadoop.yarn.server.resourcemanager.amlauncher.AMLauncher: Done launching container Container: [ContainerId: container_1429327468486_0001_01_000001, NodeId: k05n26.ccr.buffalo.edu:33870, NodeHttpAddress: k05n26.ccr.buffalo.edu:8042, Resource: <memory:2048, vCores:1>, Priority: 0, Token: Token { kind: ContainerToken, service: 10.111.5.26:33870 }, ] for AM appattempt_1429327468486_0001_000001
2015-04-17 23:24:47,797 INFO org.apache.hadoop.yarn.server.resourcemanager.rmapp.attempt.RMAppAttemptImpl: appattempt_1429327468486_0001_000001 State change from ALLOCATED to LAUNCHED
2015-04-17 23:24:48,519 INFO org.apache.hadoop.yarn.server.resourcemanager.rmcontainer.RMContainerImpl: container_1429327468486_0001_01_000001 Container Transitioned from ACQUIRED to RUNNING
2015-04-17 23:24:53,325 INFO SecurityLogger.org.apache.hadoop.ipc.Server: Auth successful for appattempt_1429327468486_0001_000001 (auth:SIMPLE)
2015-04-17 23:24:53,331 INFO org.apache.hadoop.yarn.server.resourcemanager.ApplicationMasterService: AM registration appattempt_1429327468486_0001_000001
2015-04-17 23:24:53,331 INFO org.apache.hadoop.yarn.server.resourcemanager.RMAuditLogger: USER=u2	IP=10.111.5.26	OPERATION=Register App Master	TARGET=ApplicationMasterService	RESULT=SUCCESS	APPID=application_1429327468486_0001	APPATTEMPTID=appattempt_1429327468486_0001_000001
2015-04-17 23:24:53,332 INFO org.apache.hadoop.yarn.server.resourcemanager.rmapp.attempt.RMAppAttemptImpl: appattempt_1429327468486_0001_000001 State change from LAUNCHED to RUNNING
2015-04-17 23:24:53,332 INFO org.apache.hadoop.yarn.server.resourcemanager.rmapp.RMAppImpl: application_1429327468486_0001 State change from ACCEPTED to RUNNING
2015-04-17 23:24:54,534 INFO org.apache.hadoop.yarn.server.resourcemanager.rmcontainer.RMContainerImpl: container_1429327468486_0001_01_000002 Container Transitioned from NEW to ALLOCATED
2015-04-17 23:24:54,534 INFO org.apache.hadoop.yarn.server.resourcemanager.RMAuditLogger: USER=u2	OPERATION=AM Allocated Container	TARGET=SchedulerApp	RESULT=SUCCESS	APPID=application_1429327468486_0001	CONTAINERID=container_1429327468486_0001_01_000002
2015-04-17 23:24:54,534 INFO org.apache.hadoop.yarn.server.resourcemanager.scheduler.SchedulerNode: Assigned container container_1429327468486_0001_01_000002 of capacity <memory:1024, vCores:1> on host k05n26.ccr.buffalo.edu:33870, which has 2 containers, <memory:3072, vCores:2> used and <memory:5120, vCores:6> available after allocation
2015-04-17 23:24:54,534 INFO org.apache.hadoop.yarn.server.resourcemanager.scheduler.capacity.LeafQueue: assignedContainer application attempt=appattempt_1429327468486_0001_000001 container=Container: [ContainerId: container_1429327468486_0001_01_000002, NodeId: k05n26.ccr.buffalo.edu:33870, NodeHttpAddress: k05n26.ccr.buffalo.edu:8042, Resource: <memory:1024, vCores:1>, Priority: 20, Token: null, ] queue=default: capacity=1.0, absoluteCapacity=1.0, usedResources=<memory:2048, vCores:1>, usedCapacity=0.25, absoluteUsedCapacity=0.25, numApps=1, numContainers=1 clusterResource=<memory:8192, vCores:8>
2015-04-17 23:24:54,535 INFO org.apache.hadoop.yarn.server.resourcemanager.scheduler.capacity.ParentQueue: Re-sorting assigned queue: root.default stats: default: capacity=1.0, absoluteCapacity=1.0, usedResources=<memory:3072, vCores:2>, usedCapacity=0.375, absoluteUsedCapacity=0.375, numApps=1, numContainers=2
2015-04-17 23:24:54,535 INFO org.apache.hadoop.yarn.server.resourcemanager.scheduler.capacity.ParentQueue: assignedContainer queue=root usedCapacity=0.375 absoluteUsedCapacity=0.375 used=<memory:3072, vCores:2> cluster=<memory:8192, vCores:8>
2015-04-17 23:24:54,535 INFO org.apache.hadoop.yarn.server.resourcemanager.rmcontainer.RMContainerImpl: container_1429327468486_0001_01_000003 Container Transitioned from NEW to ALLOCATED
2015-04-17 23:24:54,535 INFO org.apache.hadoop.yarn.server.resourcemanager.RMAuditLogger: USER=u2	OPERATION=AM Allocated Container	TARGET=SchedulerApp	RESULT=SUCCESS	APPID=application_1429327468486_0001	CONTAINERID=container_1429327468486_0001_01_000003
2015-04-17 23:24:54,535 INFO org.apache.hadoop.yarn.server.resourcemanager.scheduler.SchedulerNode: Assigned container container_1429327468486_0001_01_000003 of capacity <memory:1024, vCores:1> on host k05n26.ccr.buffalo.edu:33870, which has 3 containers, <memory:4096, vCores:3> used and <memory:4096, vCores:5> available after allocation
2015-04-17 23:24:54,535 INFO org.apache.hadoop.yarn.server.resourcemanager.scheduler.capacity.LeafQueue: assignedContainer application attempt=appattempt_1429327468486_0001_000001 container=Container: [ContainerId: container_1429327468486_0001_01_000003, NodeId: k05n26.ccr.buffalo.edu:33870, NodeHttpAddress: k05n26.ccr.buffalo.edu:8042, Resource: <memory:1024, vCores:1>, Priority: 20, Token: null, ] queue=default: capacity=1.0, absoluteCapacity=1.0, usedResources=<memory:3072, vCores:2>, usedCapacity=0.375, absoluteUsedCapacity=0.375, numApps=1, numContainers=2 clusterResource=<memory:8192, vCores:8>
2015-04-17 23:24:54,535 INFO org.apache.hadoop.yarn.server.resourcemanager.scheduler.capacity.ParentQueue: Re-sorting assigned queue: root.default stats: default: capacity=1.0, absoluteCapacity=1.0, usedResources=<memory:4096, vCores:3>, usedCapacity=0.5, absoluteUsedCapacity=0.5, numApps=1, numContainers=3
2015-04-17 23:24:54,535 INFO org.apache.hadoop.yarn.server.resourcemanager.scheduler.capacity.ParentQueue: assignedContainer queue=root usedCapacity=0.5 absoluteUsedCapacity=0.5 used=<memory:4096, vCores:3> cluster=<memory:8192, vCores:8>
2015-04-17 23:24:55,385 INFO org.apache.hadoop.yarn.server.resourcemanager.security.NMTokenSecretManagerInRM: Sending NMToken for nodeId : k05n26.ccr.buffalo.edu:33870 for container : container_1429327468486_0001_01_000002
2015-04-17 23:24:55,385 INFO org.apache.hadoop.yarn.server.resourcemanager.rmcontainer.RMContainerImpl: container_1429327468486_0001_01_000002 Container Transitioned from ALLOCATED to ACQUIRED
2015-04-17 23:24:55,387 INFO org.apache.hadoop.yarn.server.resourcemanager.rmcontainer.RMContainerImpl: container_1429327468486_0001_01_000003 Container Transitioned from ALLOCATED to ACQUIRED
2015-04-17 23:24:56,400 INFO org.apache.hadoop.yarn.server.resourcemanager.scheduler.AppSchedulingInfo: checking for deactivate... 
2015-04-17 23:24:56,538 INFO org.apache.hadoop.yarn.server.resourcemanager.rmcontainer.RMContainerImpl: container_1429327468486_0001_01_000002 Container Transitioned from ACQUIRED to RUNNING
2015-04-17 23:24:56,538 INFO org.apache.hadoop.yarn.server.resourcemanager.rmcontainer.RMContainerImpl: container_1429327468486_0001_01_000003 Container Transitioned from ACQUIRED to RUNNING
2015-04-17 23:24:59,086 INFO org.apache.hadoop.yarn.server.resourcemanager.rmapp.attempt.RMAppAttemptImpl: Updating application attempt appattempt_1429327468486_0001_000001 with final state: FINISHING, and exit status: -1000
2015-04-17 23:24:59,087 INFO org.apache.hadoop.yarn.server.resourcemanager.rmapp.attempt.RMAppAttemptImpl: appattempt_1429327468486_0001_000001 State change from RUNNING to FINAL_SAVING
2015-04-17 23:24:59,087 INFO org.apache.hadoop.yarn.server.resourcemanager.rmapp.RMAppImpl: Updating application application_1429327468486_0001 with final state: FINISHING
2015-04-17 23:24:59,088 INFO org.apache.hadoop.yarn.server.resourcemanager.rmapp.RMAppImpl: application_1429327468486_0001 State change from RUNNING to FINAL_SAVING
2015-04-17 23:24:59,089 INFO org.apache.hadoop.yarn.server.resourcemanager.recovery.RMStateStore: Updating info for app: application_1429327468486_0001
2015-04-17 23:24:59,090 INFO org.apache.hadoop.yarn.server.resourcemanager.rmapp.attempt.RMAppAttemptImpl: appattempt_1429327468486_0001_000001 State change from FINAL_SAVING to FINISHING
2015-04-17 23:24:59,090 INFO org.apache.hadoop.yarn.server.resourcemanager.rmapp.RMAppImpl: application_1429327468486_0001 State change from FINAL_SAVING to FINISHING
2015-04-17 23:24:59,991 INFO org.apache.hadoop.yarn.server.resourcemanager.rmcontainer.RMContainerImpl: container_1429327468486_0001_01_000002 Container Transitioned from RUNNING to COMPLETED
2015-04-17 23:24:59,991 INFO org.apache.hadoop.yarn.server.resourcemanager.scheduler.common.fica.FiCaSchedulerApp: Completed container: container_1429327468486_0001_01_000002 in state: COMPLETED event:FINISHED
2015-04-17 23:24:59,991 INFO org.apache.hadoop.yarn.server.resourcemanager.RMAuditLogger: USER=u2	OPERATION=AM Released Container	TARGET=SchedulerApp	RESULT=SUCCESS	APPID=application_1429327468486_0001	CONTAINERID=container_1429327468486_0001_01_000002
2015-04-17 23:24:59,991 INFO org.apache.hadoop.yarn.server.resourcemanager.scheduler.SchedulerNode: Released container container_1429327468486_0001_01_000002 of capacity <memory:1024, vCores:1> on host k05n26.ccr.buffalo.edu:33870, which currently has 2 containers, <memory:3072, vCores:2> used and <memory:5120, vCores:6> available, release resources=true
2015-04-17 23:24:59,991 INFO org.apache.hadoop.yarn.server.resourcemanager.scheduler.capacity.LeafQueue: default used=<memory:3072, vCores:2> numContainers=2 user=u2 user-resources=<memory:3072, vCores:2>
2015-04-17 23:24:59,991 INFO org.apache.hadoop.yarn.server.resourcemanager.scheduler.capacity.LeafQueue: completedContainer container=Container: [ContainerId: container_1429327468486_0001_01_000002, NodeId: k05n26.ccr.buffalo.edu:33870, NodeHttpAddress: k05n26.ccr.buffalo.edu:8042, Resource: <memory:1024, vCores:1>, Priority: 20, Token: Token { kind: ContainerToken, service: 10.111.5.26:33870 }, ] queue=default: capacity=1.0, absoluteCapacity=1.0, usedResources=<memory:3072, vCores:2>, usedCapacity=0.375, absoluteUsedCapacity=0.375, numApps=1, numContainers=2 cluster=<memory:8192, vCores:8>
2015-04-17 23:24:59,992 INFO org.apache.hadoop.yarn.server.resourcemanager.scheduler.capacity.ParentQueue: completedContainer queue=root usedCapacity=0.375 absoluteUsedCapacity=0.375 used=<memory:3072, vCores:2> cluster=<memory:8192, vCores:8>
2015-04-17 23:24:59,992 INFO org.apache.hadoop.yarn.server.resourcemanager.scheduler.capacity.ParentQueue: Re-sorting completed queue: root.default stats: default: capacity=1.0, absoluteCapacity=1.0, usedResources=<memory:3072, vCores:2>, usedCapacity=0.375, absoluteUsedCapacity=0.375, numApps=1, numContainers=2
2015-04-17 23:24:59,992 INFO org.apache.hadoop.yarn.server.resourcemanager.scheduler.capacity.CapacityScheduler: Application attempt appattempt_1429327468486_0001_000001 released container container_1429327468486_0001_01_000002 on node: host: k05n26.ccr.buffalo.edu:33870 #containers=2 available=5120 used=3072 with event: FINISHED
2015-04-17 23:24:59,992 INFO org.apache.hadoop.yarn.server.resourcemanager.rmcontainer.RMContainerImpl: container_1429327468486_0001_01_000003 Container Transitioned from RUNNING to COMPLETED
2015-04-17 23:24:59,992 INFO org.apache.hadoop.yarn.server.resourcemanager.scheduler.common.fica.FiCaSchedulerApp: Completed container: container_1429327468486_0001_01_000003 in state: COMPLETED event:FINISHED
2015-04-17 23:24:59,992 INFO org.apache.hadoop.yarn.server.resourcemanager.RMAuditLogger: USER=u2	OPERATION=AM Released Container	TARGET=SchedulerApp	RESULT=SUCCESS	APPID=application_1429327468486_0001	CONTAINERID=container_1429327468486_0001_01_000003
2015-04-17 23:24:59,992 INFO org.apache.hadoop.yarn.server.resourcemanager.scheduler.SchedulerNode: Released container container_1429327468486_0001_01_000003 of capacity <memory:1024, vCores:1> on host k05n26.ccr.buffalo.edu:33870, which currently has 1 containers, <memory:2048, vCores:1> used and <memory:6144, vCores:7> available, release resources=true
2015-04-17 23:24:59,992 INFO org.apache.hadoop.yarn.server.resourcemanager.scheduler.capacity.LeafQueue: default used=<memory:2048, vCores:1> numContainers=1 user=u2 user-resources=<memory:2048, vCores:1>
2015-04-17 23:24:59,992 INFO org.apache.hadoop.yarn.server.resourcemanager.scheduler.capacity.LeafQueue: completedContainer container=Container: [ContainerId: container_1429327468486_0001_01_000003, NodeId: k05n26.ccr.buffalo.edu:33870, NodeHttpAddress: k05n26.ccr.buffalo.edu:8042, Resource: <memory:1024, vCores:1>, Priority: 20, Token: Token { kind: ContainerToken, service: 10.111.5.26:33870 }, ] queue=default: capacity=1.0, absoluteCapacity=1.0, usedResources=<memory:2048, vCores:1>, usedCapacity=0.25, absoluteUsedCapacity=0.25, numApps=1, numContainers=1 cluster=<memory:8192, vCores:8>
2015-04-17 23:24:59,992 INFO org.apache.hadoop.yarn.server.resourcemanager.scheduler.capacity.ParentQueue: completedContainer queue=root usedCapacity=0.25 absoluteUsedCapacity=0.25 used=<memory:2048, vCores:1> cluster=<memory:8192, vCores:8>
2015-04-17 23:24:59,992 INFO org.apache.hadoop.yarn.server.resourcemanager.scheduler.capacity.ParentQueue: Re-sorting completed queue: root.default stats: default: capacity=1.0, absoluteCapacity=1.0, usedResources=<memory:2048, vCores:1>, usedCapacity=0.25, absoluteUsedCapacity=0.25, numApps=1, numContainers=1
2015-04-17 23:24:59,993 INFO org.apache.hadoop.yarn.server.resourcemanager.scheduler.capacity.CapacityScheduler: Application attempt appattempt_1429327468486_0001_000001 released container container_1429327468486_0001_01_000003 on node: host: k05n26.ccr.buffalo.edu:33870 #containers=1 available=6144 used=2048 with event: FINISHED
2015-04-17 23:25:01,205 INFO org.apache.hadoop.yarn.server.resourcemanager.ClientRMService: Allocated new applicationId: 2
2015-04-17 23:25:01,621 INFO org.apache.hadoop.yarn.server.resourcemanager.ClientRMService: Application with id 2 submitted by user u2
2015-04-17 23:25:01,621 INFO org.apache.hadoop.yarn.server.resourcemanager.rmapp.RMAppImpl: Storing application with id application_1429327468486_0002
2015-04-17 23:25:01,621 INFO org.apache.hadoop.yarn.server.resourcemanager.RMAuditLogger: USER=u2	IP=10.111.5.26	OPERATION=Submit Application Request	TARGET=ClientRMService	RESULT=SUCCESS	APPID=application_1429327468486_0002
2015-04-17 23:25:01,621 INFO org.apache.hadoop.yarn.server.resourcemanager.rmapp.RMAppImpl: application_1429327468486_0002 State change from NEW to NEW_SAVING
2015-04-17 23:25:01,621 INFO org.apache.hadoop.yarn.server.resourcemanager.recovery.RMStateStore: Storing info for app: application_1429327468486_0002
2015-04-17 23:25:01,621 INFO org.apache.hadoop.yarn.server.resourcemanager.rmapp.RMAppImpl: application_1429327468486_0002 State change from NEW_SAVING to SUBMITTED
2015-04-17 23:25:01,622 INFO org.apache.hadoop.yarn.server.resourcemanager.scheduler.capacity.ParentQueue: Application added - appId: application_1429327468486_0002 user: u2 leaf-queue of parent: root #applications: 2
2015-04-17 23:25:01,622 INFO org.apache.hadoop.yarn.server.resourcemanager.scheduler.capacity.CapacityScheduler: Accepted application application_1429327468486_0002 from user: u2, in queue: default
2015-04-17 23:25:01,622 INFO org.apache.hadoop.yarn.server.resourcemanager.rmapp.RMAppImpl: application_1429327468486_0002 State change from SUBMITTED to ACCEPTED
2015-04-17 23:25:01,622 INFO org.apache.hadoop.yarn.server.resourcemanager.ApplicationMasterService: Registering app attempt : appattempt_1429327468486_0002_000001
2015-04-17 23:25:01,622 INFO org.apache.hadoop.yarn.server.resourcemanager.rmapp.attempt.RMAppAttemptImpl: appattempt_1429327468486_0002_000001 State change from NEW to SUBMITTED
2015-04-17 23:25:01,623 INFO org.apache.hadoop.yarn.server.resourcemanager.scheduler.capacity.LeafQueue: Application added - appId: application_1429327468486_0002 user: org.apache.hadoop.yarn.server.resourcemanager.scheduler.capacity.LeafQueue$User@4599d5b, leaf-queue: default #user-pending-applications: 1 #user-active-applications: 1 #queue-pending-applications: 1 #queue-active-applications: 1
2015-04-17 23:25:01,623 INFO org.apache.hadoop.yarn.server.resourcemanager.scheduler.capacity.CapacityScheduler: Added Application Attempt appattempt_1429327468486_0002_000001 to scheduler from user u2 in queue default
2015-04-17 23:25:01,623 INFO org.apache.hadoop.yarn.server.resourcemanager.rmapp.attempt.RMAppAttemptImpl: appattempt_1429327468486_0002_000001 State change from SUBMITTED to SCHEDULED
2015-04-17 23:25:06,000 INFO org.apache.hadoop.yarn.server.resourcemanager.rmcontainer.RMContainerImpl: container_1429327468486_0001_01_000001 Container Transitioned from RUNNING to COMPLETED
2015-04-17 23:25:06,000 INFO org.apache.hadoop.yarn.server.resourcemanager.scheduler.common.fica.FiCaSchedulerApp: Completed container: container_1429327468486_0001_01_000001 in state: COMPLETED event:FINISHED
2015-04-17 23:25:06,000 INFO org.apache.hadoop.yarn.server.resourcemanager.ApplicationMasterService: Unregistering app attempt : appattempt_1429327468486_0001_000001
2015-04-17 23:25:06,000 INFO org.apache.hadoop.yarn.server.resourcemanager.RMAuditLogger: USER=u2	OPERATION=AM Released Container	TARGET=SchedulerApp	RESULT=SUCCESS	APPID=application_1429327468486_0001	CONTAINERID=container_1429327468486_0001_01_000001
2015-04-17 23:25:06,000 INFO org.apache.hadoop.yarn.server.resourcemanager.scheduler.SchedulerNode: Released container container_1429327468486_0001_01_000001 of capacity <memory:2048, vCores:1> on host k05n26.ccr.buffalo.edu:33870, which currently has 0 containers, <memory:0, vCores:0> used and <memory:8192, vCores:8> available, release resources=true
2015-04-17 23:25:06,000 INFO org.apache.hadoop.yarn.server.resourcemanager.scheduler.capacity.LeafQueue: default used=<memory:0, vCores:0> numContainers=0 user=u2 user-resources=<memory:0, vCores:0>
2015-04-17 23:25:06,000 INFO org.apache.hadoop.yarn.server.resourcemanager.scheduler.capacity.LeafQueue: completedContainer container=Container: [ContainerId: container_1429327468486_0001_01_000001, NodeId: k05n26.ccr.buffalo.edu:33870, NodeHttpAddress: k05n26.ccr.buffalo.edu:8042, Resource: <memory:2048, vCores:1>, Priority: 0, Token: Token { kind: ContainerToken, service: 10.111.5.26:33870 }, ] queue=default: capacity=1.0, absoluteCapacity=1.0, usedResources=<memory:0, vCores:0>, usedCapacity=0.0, absoluteUsedCapacity=0.0, numApps=2, numContainers=0 cluster=<memory:8192, vCores:8>
2015-04-17 23:25:06,000 INFO org.apache.hadoop.yarn.server.resourcemanager.scheduler.capacity.ParentQueue: completedContainer queue=root usedCapacity=0.0 absoluteUsedCapacity=0.0 used=<memory:0, vCores:0> cluster=<memory:8192, vCores:8>
2015-04-17 23:25:06,000 INFO org.apache.hadoop.yarn.server.resourcemanager.scheduler.capacity.ParentQueue: Re-sorting completed queue: root.default stats: default: capacity=1.0, absoluteCapacity=1.0, usedResources=<memory:0, vCores:0>, usedCapacity=0.0, absoluteUsedCapacity=0.0, numApps=2, numContainers=0
2015-04-17 23:25:06,000 INFO org.apache.hadoop.yarn.server.resourcemanager.scheduler.capacity.CapacityScheduler: Application attempt appattempt_1429327468486_0001_000001 released container container_1429327468486_0001_01_000001 on node: host: k05n26.ccr.buffalo.edu:33870 #containers=0 available=8192 used=0 with event: FINISHED
2015-04-17 23:25:06,001 INFO org.apache.hadoop.yarn.server.resourcemanager.rmapp.attempt.RMAppAttemptImpl: appattempt_1429327468486_0001_000001 State change from FINISHING to FINISHED
2015-04-17 23:25:06,002 INFO org.apache.hadoop.yarn.server.resourcemanager.rmapp.RMAppImpl: application_1429327468486_0001 State change from FINISHING to FINISHED
2015-04-17 23:25:06,003 INFO org.apache.hadoop.yarn.server.resourcemanager.scheduler.capacity.CapacityScheduler: Application Attempt appattempt_1429327468486_0001_000001 is done. finalState=FINISHED
2015-04-17 23:25:06,003 INFO org.apache.hadoop.yarn.server.resourcemanager.scheduler.AppSchedulingInfo: Application application_1429327468486_0001 requests cleared
2015-04-17 23:25:06,003 INFO org.apache.hadoop.yarn.server.resourcemanager.scheduler.capacity.LeafQueue: Application application_1429327468486_0002 from user: u2 activated in queue: default
2015-04-17 23:25:06,003 INFO org.apache.hadoop.yarn.server.resourcemanager.scheduler.capacity.LeafQueue: Application removed - appId: application_1429327468486_0001 user: u2 queue: default #user-pending-applications: 0 #user-active-applications: 1 #queue-pending-applications: 0 #queue-active-applications: 1
2015-04-17 23:25:06,003 INFO org.apache.hadoop.yarn.server.resourcemanager.amlauncher.AMLauncher: Cleaning master appattempt_1429327468486_0001_000001
2015-04-17 23:25:06,004 INFO org.apache.hadoop.yarn.server.resourcemanager.scheduler.capacity.ParentQueue: Application removed - appId: application_1429327468486_0001 user: u2 leaf-queue of parent: root #applications: 1
2015-04-17 23:25:06,004 INFO org.apache.hadoop.yarn.server.resourcemanager.RMAuditLogger: USER=u2	OPERATION=Application Finished - Succeeded	TARGET=RMAppManager	RESULT=SUCCESS	APPID=application_1429327468486_0001
2015-04-17 23:25:06,006 INFO org.apache.hadoop.yarn.server.resourcemanager.RMAppManager$ApplicationSummary: appId=application_1429327468486_0001,name=hw4.jar,user=u2,queue=default,state=FINISHED,trackingUrl=http://k05n26:8088/proxy/application_1429327468486_0001/jobhistory/job/job_1429327468486_0001,appMasterHost=k05n26,startTime=1429327486593,finishTime=1429327499087,finalStatus=SUCCEEDED
2015-04-17 23:25:07,002 INFO org.apache.hadoop.yarn.server.resourcemanager.rmcontainer.RMContainerImpl: container_1429327468486_0002_01_000001 Container Transitioned from NEW to ALLOCATED
2015-04-17 23:25:07,002 INFO org.apache.hadoop.yarn.server.resourcemanager.RMAuditLogger: USER=u2	OPERATION=AM Allocated Container	TARGET=SchedulerApp	RESULT=SUCCESS	APPID=application_1429327468486_0002	CONTAINERID=container_1429327468486_0002_01_000001
2015-04-17 23:25:07,002 INFO org.apache.hadoop.yarn.server.resourcemanager.scheduler.SchedulerNode: Assigned container container_1429327468486_0002_01_000001 of capacity <memory:2048, vCores:1> on host k05n26.ccr.buffalo.edu:33870, which has 1 containers, <memory:2048, vCores:1> used and <memory:6144, vCores:7> available after allocation
2015-04-17 23:25:07,002 INFO org.apache.hadoop.yarn.server.resourcemanager.scheduler.capacity.LeafQueue: assignedContainer application attempt=appattempt_1429327468486_0002_000001 container=Container: [ContainerId: container_1429327468486_0002_01_000001, NodeId: k05n26.ccr.buffalo.edu:33870, NodeHttpAddress: k05n26.ccr.buffalo.edu:8042, Resource: <memory:2048, vCores:1>, Priority: 0, Token: null, ] queue=default: capacity=1.0, absoluteCapacity=1.0, usedResources=<memory:0, vCores:0>, usedCapacity=0.0, absoluteUsedCapacity=0.0, numApps=1, numContainers=0 clusterResource=<memory:8192, vCores:8>
2015-04-17 23:25:07,002 INFO org.apache.hadoop.yarn.server.resourcemanager.scheduler.capacity.ParentQueue: Re-sorting assigned queue: root.default stats: default: capacity=1.0, absoluteCapacity=1.0, usedResources=<memory:2048, vCores:1>, usedCapacity=0.25, absoluteUsedCapacity=0.25, numApps=1, numContainers=1
2015-04-17 23:25:07,002 INFO org.apache.hadoop.yarn.server.resourcemanager.scheduler.capacity.ParentQueue: assignedContainer queue=root usedCapacity=0.25 absoluteUsedCapacity=0.25 used=<memory:2048, vCores:1> cluster=<memory:8192, vCores:8>
2015-04-17 23:25:07,002 INFO org.apache.hadoop.yarn.server.resourcemanager.security.NMTokenSecretManagerInRM: Sending NMToken for nodeId : k05n26.ccr.buffalo.edu:33870 for container : container_1429327468486_0002_01_000001
2015-04-17 23:25:07,003 INFO org.apache.hadoop.yarn.server.resourcemanager.rmcontainer.RMContainerImpl: container_1429327468486_0002_01_000001 Container Transitioned from ALLOCATED to ACQUIRED
2015-04-17 23:25:07,003 INFO org.apache.hadoop.yarn.server.resourcemanager.security.NMTokenSecretManagerInRM: Clear node set for appattempt_1429327468486_0002_000001
2015-04-17 23:25:07,003 INFO org.apache.hadoop.yarn.server.resourcemanager.rmapp.attempt.RMAppAttemptImpl: Storing attempt: AppId: application_1429327468486_0002 AttemptId: appattempt_1429327468486_0002_000001 MasterContainer: Container: [ContainerId: container_1429327468486_0002_01_000001, NodeId: k05n26.ccr.buffalo.edu:33870, NodeHttpAddress: k05n26.ccr.buffalo.edu:8042, Resource: <memory:2048, vCores:1>, Priority: 0, Token: Token { kind: ContainerToken, service: 10.111.5.26:33870 }, ]
2015-04-17 23:25:07,003 INFO org.apache.hadoop.yarn.server.resourcemanager.rmapp.attempt.RMAppAttemptImpl: appattempt_1429327468486_0002_000001 State change from SCHEDULED to ALLOCATED_SAVING
2015-04-17 23:25:07,003 INFO org.apache.hadoop.yarn.server.resourcemanager.rmapp.attempt.RMAppAttemptImpl: appattempt_1429327468486_0002_000001 State change from ALLOCATED_SAVING to ALLOCATED
2015-04-17 23:25:07,004 INFO org.apache.hadoop.yarn.server.resourcemanager.amlauncher.AMLauncher: Launching masterappattempt_1429327468486_0002_000001
2015-04-17 23:25:07,005 INFO org.apache.hadoop.yarn.server.resourcemanager.amlauncher.AMLauncher: Setting up container Container: [ContainerId: container_1429327468486_0002_01_000001, NodeId: k05n26.ccr.buffalo.edu:33870, NodeHttpAddress: k05n26.ccr.buffalo.edu:8042, Resource: <memory:2048, vCores:1>, Priority: 0, Token: Token { kind: ContainerToken, service: 10.111.5.26:33870 }, ] for AM appattempt_1429327468486_0002_000001
2015-04-17 23:25:07,005 INFO org.apache.hadoop.yarn.server.resourcemanager.amlauncher.AMLauncher: Command to launch container container_1429327468486_0002_01_000001 : $JAVA_HOME/bin/java -Dlog4j.configuration=container-log4j.properties -Dyarn.app.container.log.dir=<LOG_DIR> -Dyarn.app.container.log.filesize=0 -Dhadoop.root.logger=INFO,CLA  -Xmx1024m org.apache.hadoop.mapreduce.v2.app.MRAppMaster 1><LOG_DIR>/stdout 2><LOG_DIR>/stderr 
2015-04-17 23:25:07,014 INFO org.apache.hadoop.yarn.server.resourcemanager.amlauncher.AMLauncher: Done launching container Container: [ContainerId: container_1429327468486_0002_01_000001, NodeId: k05n26.ccr.buffalo.edu:33870, NodeHttpAddress: k05n26.ccr.buffalo.edu:8042, Resource: <memory:2048, vCores:1>, Priority: 0, Token: Token { kind: ContainerToken, service: 10.111.5.26:33870 }, ] for AM appattempt_1429327468486_0002_000001
2015-04-17 23:25:07,014 INFO org.apache.hadoop.yarn.server.resourcemanager.rmapp.attempt.RMAppAttemptImpl: appattempt_1429327468486_0002_000001 State change from ALLOCATED to LAUNCHED
2015-04-17 23:25:08,005 INFO org.apache.hadoop.yarn.server.resourcemanager.rmcontainer.RMContainerImpl: container_1429327468486_0002_01_000001 Container Transitioned from ACQUIRED to RUNNING
2015-04-17 23:25:11,851 INFO SecurityLogger.org.apache.hadoop.ipc.Server: Auth successful for appattempt_1429327468486_0002_000001 (auth:SIMPLE)
2015-04-17 23:25:11,853 INFO org.apache.hadoop.yarn.server.resourcemanager.ApplicationMasterService: AM registration appattempt_1429327468486_0002_000001
2015-04-17 23:25:11,854 INFO org.apache.hadoop.yarn.server.resourcemanager.RMAuditLogger: USER=u2	IP=10.111.5.26	OPERATION=Register App Master	TARGET=ApplicationMasterService	RESULT=SUCCESS	APPID=application_1429327468486_0002	APPATTEMPTID=appattempt_1429327468486_0002_000001
2015-04-17 23:25:11,854 INFO org.apache.hadoop.yarn.server.resourcemanager.rmapp.attempt.RMAppAttemptImpl: appattempt_1429327468486_0002_000001 State change from LAUNCHED to RUNNING
2015-04-17 23:25:11,854 INFO org.apache.hadoop.yarn.server.resourcemanager.rmapp.RMAppImpl: application_1429327468486_0002 State change from ACCEPTED to RUNNING
2015-04-17 23:25:13,021 INFO org.apache.hadoop.yarn.server.resourcemanager.rmcontainer.RMContainerImpl: container_1429327468486_0002_01_000002 Container Transitioned from NEW to ALLOCATED
2015-04-17 23:25:13,021 INFO org.apache.hadoop.yarn.server.resourcemanager.RMAuditLogger: USER=u2	OPERATION=AM Allocated Container	TARGET=SchedulerApp	RESULT=SUCCESS	APPID=application_1429327468486_0002	CONTAINERID=container_1429327468486_0002_01_000002
2015-04-17 23:25:13,021 INFO org.apache.hadoop.yarn.server.resourcemanager.scheduler.SchedulerNode: Assigned container container_1429327468486_0002_01_000002 of capacity <memory:1024, vCores:1> on host k05n26.ccr.buffalo.edu:33870, which has 2 containers, <memory:3072, vCores:2> used and <memory:5120, vCores:6> available after allocation
2015-04-17 23:25:13,021 INFO org.apache.hadoop.yarn.server.resourcemanager.scheduler.capacity.LeafQueue: assignedContainer application attempt=appattempt_1429327468486_0002_000001 container=Container: [ContainerId: container_1429327468486_0002_01_000002, NodeId: k05n26.ccr.buffalo.edu:33870, NodeHttpAddress: k05n26.ccr.buffalo.edu:8042, Resource: <memory:1024, vCores:1>, Priority: 20, Token: null, ] queue=default: capacity=1.0, absoluteCapacity=1.0, usedResources=<memory:2048, vCores:1>, usedCapacity=0.25, absoluteUsedCapacity=0.25, numApps=1, numContainers=1 clusterResource=<memory:8192, vCores:8>
2015-04-17 23:25:13,021 INFO org.apache.hadoop.yarn.server.resourcemanager.scheduler.capacity.ParentQueue: Re-sorting assigned queue: root.default stats: default: capacity=1.0, absoluteCapacity=1.0, usedResources=<memory:3072, vCores:2>, usedCapacity=0.375, absoluteUsedCapacity=0.375, numApps=1, numContainers=2
2015-04-17 23:25:13,022 INFO org.apache.hadoop.yarn.server.resourcemanager.scheduler.capacity.ParentQueue: assignedContainer queue=root usedCapacity=0.375 absoluteUsedCapacity=0.375 used=<memory:3072, vCores:2> cluster=<memory:8192, vCores:8>
2015-04-17 23:25:13,891 INFO org.apache.hadoop.yarn.server.resourcemanager.security.NMTokenSecretManagerInRM: Sending NMToken for nodeId : k05n26.ccr.buffalo.edu:33870 for container : container_1429327468486_0002_01_000002
2015-04-17 23:25:13,892 INFO org.apache.hadoop.yarn.server.resourcemanager.rmcontainer.RMContainerImpl: container_1429327468486_0002_01_000002 Container Transitioned from ALLOCATED to ACQUIRED
2015-04-17 23:25:14,902 INFO org.apache.hadoop.yarn.server.resourcemanager.scheduler.AppSchedulingInfo: checking for deactivate... 
2015-04-17 23:25:15,025 INFO org.apache.hadoop.yarn.server.resourcemanager.rmcontainer.RMContainerImpl: container_1429327468486_0002_01_000002 Container Transitioned from ACQUIRED to RUNNING
2015-04-17 23:25:18,010 INFO org.apache.hadoop.yarn.server.resourcemanager.rmcontainer.RMContainerImpl: container_1429327468486_0002_01_000002 Container Transitioned from RUNNING to COMPLETED
2015-04-17 23:25:18,011 INFO org.apache.hadoop.yarn.server.resourcemanager.scheduler.common.fica.FiCaSchedulerApp: Completed container: container_1429327468486_0002_01_000002 in state: COMPLETED event:FINISHED
2015-04-17 23:25:18,011 INFO org.apache.hadoop.yarn.server.resourcemanager.RMAuditLogger: USER=u2	OPERATION=AM Released Container	TARGET=SchedulerApp	RESULT=SUCCESS	APPID=application_1429327468486_0002	CONTAINERID=container_1429327468486_0002_01_000002
2015-04-17 23:25:18,011 INFO org.apache.hadoop.yarn.server.resourcemanager.scheduler.SchedulerNode: Released container container_1429327468486_0002_01_000002 of capacity <memory:1024, vCores:1> on host k05n26.ccr.buffalo.edu:33870, which currently has 1 containers, <memory:2048, vCores:1> used and <memory:6144, vCores:7> available, release resources=true
2015-04-17 23:25:18,011 INFO org.apache.hadoop.yarn.server.resourcemanager.scheduler.capacity.LeafQueue: default used=<memory:2048, vCores:1> numContainers=1 user=u2 user-resources=<memory:2048, vCores:1>
2015-04-17 23:25:18,011 INFO org.apache.hadoop.yarn.server.resourcemanager.scheduler.capacity.LeafQueue: completedContainer container=Container: [ContainerId: container_1429327468486_0002_01_000002, NodeId: k05n26.ccr.buffalo.edu:33870, NodeHttpAddress: k05n26.ccr.buffalo.edu:8042, Resource: <memory:1024, vCores:1>, Priority: 20, Token: Token { kind: ContainerToken, service: 10.111.5.26:33870 }, ] queue=default: capacity=1.0, absoluteCapacity=1.0, usedResources=<memory:2048, vCores:1>, usedCapacity=0.25, absoluteUsedCapacity=0.25, numApps=1, numContainers=1 cluster=<memory:8192, vCores:8>
2015-04-17 23:25:18,011 INFO org.apache.hadoop.yarn.server.resourcemanager.scheduler.capacity.ParentQueue: completedContainer queue=root usedCapacity=0.25 absoluteUsedCapacity=0.25 used=<memory:2048, vCores:1> cluster=<memory:8192, vCores:8>
2015-04-17 23:25:18,011 INFO org.apache.hadoop.yarn.server.resourcemanager.scheduler.capacity.ParentQueue: Re-sorting completed queue: root.default stats: default: capacity=1.0, absoluteCapacity=1.0, usedResources=<memory:2048, vCores:1>, usedCapacity=0.25, absoluteUsedCapacity=0.25, numApps=1, numContainers=1
2015-04-17 23:25:18,011 INFO org.apache.hadoop.yarn.server.resourcemanager.scheduler.capacity.CapacityScheduler: Application attempt appattempt_1429327468486_0002_000001 released container container_1429327468486_0002_01_000002 on node: host: k05n26.ccr.buffalo.edu:33870 #containers=1 available=6144 used=2048 with event: FINISHED
2015-04-17 23:25:19,012 INFO org.apache.hadoop.yarn.server.resourcemanager.rmcontainer.RMContainerImpl: container_1429327468486_0002_01_000003 Container Transitioned from NEW to ALLOCATED
2015-04-17 23:25:19,012 INFO org.apache.hadoop.yarn.server.resourcemanager.RMAuditLogger: USER=u2	OPERATION=AM Allocated Container	TARGET=SchedulerApp	RESULT=SUCCESS	APPID=application_1429327468486_0002	CONTAINERID=container_1429327468486_0002_01_000003
2015-04-17 23:25:19,012 INFO org.apache.hadoop.yarn.server.resourcemanager.scheduler.SchedulerNode: Assigned container container_1429327468486_0002_01_000003 of capacity <memory:1024, vCores:1> on host k05n26.ccr.buffalo.edu:33870, which has 2 containers, <memory:3072, vCores:2> used and <memory:5120, vCores:6> available after allocation
2015-04-17 23:25:19,012 INFO org.apache.hadoop.yarn.server.resourcemanager.scheduler.capacity.LeafQueue: assignedContainer application attempt=appattempt_1429327468486_0002_000001 container=Container: [ContainerId: container_1429327468486_0002_01_000003, NodeId: k05n26.ccr.buffalo.edu:33870, NodeHttpAddress: k05n26.ccr.buffalo.edu:8042, Resource: <memory:1024, vCores:1>, Priority: 10, Token: null, ] queue=default: capacity=1.0, absoluteCapacity=1.0, usedResources=<memory:2048, vCores:1>, usedCapacity=0.25, absoluteUsedCapacity=0.25, numApps=1, numContainers=1 clusterResource=<memory:8192, vCores:8>
2015-04-17 23:25:19,012 INFO org.apache.hadoop.yarn.server.resourcemanager.scheduler.capacity.ParentQueue: Re-sorting assigned queue: root.default stats: default: capacity=1.0, absoluteCapacity=1.0, usedResources=<memory:3072, vCores:2>, usedCapacity=0.375, absoluteUsedCapacity=0.375, numApps=1, numContainers=2
2015-04-17 23:25:19,012 INFO org.apache.hadoop.yarn.server.resourcemanager.scheduler.capacity.ParentQueue: assignedContainer queue=root usedCapacity=0.375 absoluteUsedCapacity=0.375 used=<memory:3072, vCores:2> cluster=<memory:8192, vCores:8>
2015-04-17 23:25:19,919 INFO org.apache.hadoop.yarn.server.resourcemanager.rmcontainer.RMContainerImpl: container_1429327468486_0002_01_000003 Container Transitioned from ALLOCATED to ACQUIRED
2015-04-17 23:25:20,014 INFO org.apache.hadoop.yarn.server.resourcemanager.rmcontainer.RMContainerImpl: container_1429327468486_0002_01_000003 Container Transitioned from ACQUIRED to RUNNING
2015-04-17 23:25:20,922 INFO org.apache.hadoop.yarn.server.resourcemanager.scheduler.AppSchedulingInfo: checking for deactivate... 
2015-04-17 23:25:22,960 INFO org.apache.hadoop.yarn.server.resourcemanager.rmapp.attempt.RMAppAttemptImpl: Updating application attempt appattempt_1429327468486_0002_000001 with final state: FINISHING, and exit status: -1000
2015-04-17 23:25:22,960 INFO org.apache.hadoop.yarn.server.resourcemanager.rmapp.attempt.RMAppAttemptImpl: appattempt_1429327468486_0002_000001 State change from RUNNING to FINAL_SAVING
2015-04-17 23:25:22,961 INFO org.apache.hadoop.yarn.server.resourcemanager.rmapp.RMAppImpl: Updating application application_1429327468486_0002 with final state: FINISHING
2015-04-17 23:25:22,961 INFO org.apache.hadoop.yarn.server.resourcemanager.rmapp.RMAppImpl: application_1429327468486_0002 State change from RUNNING to FINAL_SAVING
2015-04-17 23:25:22,961 INFO org.apache.hadoop.yarn.server.resourcemanager.recovery.RMStateStore: Updating info for app: application_1429327468486_0002
2015-04-17 23:25:22,961 INFO org.apache.hadoop.yarn.server.resourcemanager.rmapp.attempt.RMAppAttemptImpl: appattempt_1429327468486_0002_000001 State change from FINAL_SAVING to FINISHING
2015-04-17 23:25:22,961 INFO org.apache.hadoop.yarn.server.resourcemanager.rmapp.RMAppImpl: application_1429327468486_0002 State change from FINAL_SAVING to FINISHING
2015-04-17 23:25:23,884 INFO org.apache.hadoop.yarn.server.resourcemanager.rmcontainer.RMContainerImpl: container_1429327468486_0002_01_000003 Container Transitioned from RUNNING to COMPLETED
2015-04-17 23:25:23,884 INFO org.apache.hadoop.yarn.server.resourcemanager.scheduler.common.fica.FiCaSchedulerApp: Completed container: container_1429327468486_0002_01_000003 in state: COMPLETED event:FINISHED
2015-04-17 23:25:23,884 INFO org.apache.hadoop.yarn.server.resourcemanager.RMAuditLogger: USER=u2	OPERATION=AM Released Container	TARGET=SchedulerApp	RESULT=SUCCESS	APPID=application_1429327468486_0002	CONTAINERID=container_1429327468486_0002_01_000003
2015-04-17 23:25:23,884 INFO org.apache.hadoop.yarn.server.resourcemanager.scheduler.SchedulerNode: Released container container_1429327468486_0002_01_000003 of capacity <memory:1024, vCores:1> on host k05n26.ccr.buffalo.edu:33870, which currently has 1 containers, <memory:2048, vCores:1> used and <memory:6144, vCores:7> available, release resources=true
2015-04-17 23:25:23,885 INFO org.apache.hadoop.yarn.server.resourcemanager.scheduler.capacity.LeafQueue: default used=<memory:2048, vCores:1> numContainers=1 user=u2 user-resources=<memory:2048, vCores:1>
2015-04-17 23:25:23,885 INFO org.apache.hadoop.yarn.server.resourcemanager.scheduler.capacity.LeafQueue: completedContainer container=Container: [ContainerId: container_1429327468486_0002_01_000003, NodeId: k05n26.ccr.buffalo.edu:33870, NodeHttpAddress: k05n26.ccr.buffalo.edu:8042, Resource: <memory:1024, vCores:1>, Priority: 10, Token: Token { kind: ContainerToken, service: 10.111.5.26:33870 }, ] queue=default: capacity=1.0, absoluteCapacity=1.0, usedResources=<memory:2048, vCores:1>, usedCapacity=0.25, absoluteUsedCapacity=0.25, numApps=1, numContainers=1 cluster=<memory:8192, vCores:8>
2015-04-17 23:25:23,885 INFO org.apache.hadoop.yarn.server.resourcemanager.scheduler.capacity.ParentQueue: completedContainer queue=root usedCapacity=0.25 absoluteUsedCapacity=0.25 used=<memory:2048, vCores:1> cluster=<memory:8192, vCores:8>
2015-04-17 23:25:23,885 INFO org.apache.hadoop.yarn.server.resourcemanager.scheduler.capacity.ParentQueue: Re-sorting completed queue: root.default stats: default: capacity=1.0, absoluteCapacity=1.0, usedResources=<memory:2048, vCores:1>, usedCapacity=0.25, absoluteUsedCapacity=0.25, numApps=1, numContainers=1
2015-04-17 23:25:23,885 INFO org.apache.hadoop.yarn.server.resourcemanager.scheduler.capacity.CapacityScheduler: Application attempt appattempt_1429327468486_0002_000001 released container container_1429327468486_0002_01_000003 on node: host: k05n26.ccr.buffalo.edu:33870 #containers=1 available=6144 used=2048 with event: FINISHED
2015-04-17 23:25:25,109 INFO org.apache.hadoop.yarn.server.resourcemanager.ClientRMService: Allocated new applicationId: 3
2015-04-17 23:25:25,495 INFO org.apache.hadoop.yarn.server.resourcemanager.ClientRMService: Application with id 3 submitted by user u2
2015-04-17 23:25:25,495 INFO org.apache.hadoop.yarn.server.resourcemanager.RMAuditLogger: USER=u2	IP=10.111.5.26	OPERATION=Submit Application Request	TARGET=ClientRMService	RESULT=SUCCESS	APPID=application_1429327468486_0003
2015-04-17 23:25:25,495 INFO org.apache.hadoop.yarn.server.resourcemanager.rmapp.RMAppImpl: Storing application with id application_1429327468486_0003
2015-04-17 23:25:25,495 INFO org.apache.hadoop.yarn.server.resourcemanager.rmapp.RMAppImpl: application_1429327468486_0003 State change from NEW to NEW_SAVING
2015-04-17 23:25:25,495 INFO org.apache.hadoop.yarn.server.resourcemanager.recovery.RMStateStore: Storing info for app: application_1429327468486_0003
2015-04-17 23:25:25,495 INFO org.apache.hadoop.yarn.server.resourcemanager.rmapp.RMAppImpl: application_1429327468486_0003 State change from NEW_SAVING to SUBMITTED
2015-04-17 23:25:25,496 INFO org.apache.hadoop.yarn.server.resourcemanager.scheduler.capacity.ParentQueue: Application added - appId: application_1429327468486_0003 user: u2 leaf-queue of parent: root #applications: 2
2015-04-17 23:25:25,496 INFO org.apache.hadoop.yarn.server.resourcemanager.scheduler.capacity.CapacityScheduler: Accepted application application_1429327468486_0003 from user: u2, in queue: default
2015-04-17 23:25:25,496 INFO org.apache.hadoop.yarn.server.resourcemanager.rmapp.RMAppImpl: application_1429327468486_0003 State change from SUBMITTED to ACCEPTED
2015-04-17 23:25:25,496 INFO org.apache.hadoop.yarn.server.resourcemanager.ApplicationMasterService: Registering app attempt : appattempt_1429327468486_0003_000001
2015-04-17 23:25:25,496 INFO org.apache.hadoop.yarn.server.resourcemanager.rmapp.attempt.RMAppAttemptImpl: appattempt_1429327468486_0003_000001 State change from NEW to SUBMITTED
2015-04-17 23:25:25,497 INFO org.apache.hadoop.yarn.server.resourcemanager.scheduler.capacity.LeafQueue: Application added - appId: application_1429327468486_0003 user: org.apache.hadoop.yarn.server.resourcemanager.scheduler.capacity.LeafQueue$User@4599d5b, leaf-queue: default #user-pending-applications: 1 #user-active-applications: 1 #queue-pending-applications: 1 #queue-active-applications: 1
2015-04-17 23:25:25,497 INFO org.apache.hadoop.yarn.server.resourcemanager.scheduler.capacity.CapacityScheduler: Added Application Attempt appattempt_1429327468486_0003_000001 to scheduler from user u2 in queue default
2015-04-17 23:25:25,497 INFO org.apache.hadoop.yarn.server.resourcemanager.rmapp.attempt.RMAppAttemptImpl: appattempt_1429327468486_0003_000001 State change from SUBMITTED to SCHEDULED
2015-04-17 23:25:29,893 INFO org.apache.hadoop.yarn.server.resourcemanager.rmcontainer.RMContainerImpl: container_1429327468486_0002_01_000001 Container Transitioned from RUNNING to COMPLETED
2015-04-17 23:25:29,894 INFO org.apache.hadoop.yarn.server.resourcemanager.ApplicationMasterService: Unregistering app attempt : appattempt_1429327468486_0002_000001
2015-04-17 23:25:29,894 INFO org.apache.hadoop.yarn.server.resourcemanager.scheduler.common.fica.FiCaSchedulerApp: Completed container: container_1429327468486_0002_01_000001 in state: COMPLETED event:FINISHED
2015-04-17 23:25:29,894 INFO org.apache.hadoop.yarn.server.resourcemanager.rmapp.attempt.RMAppAttemptImpl: appattempt_1429327468486_0002_000001 State change from FINISHING to FINISHED
2015-04-17 23:25:29,894 INFO org.apache.hadoop.yarn.server.resourcemanager.RMAuditLogger: USER=u2	OPERATION=AM Released Container	TARGET=SchedulerApp	RESULT=SUCCESS	APPID=application_1429327468486_0002	CONTAINERID=container_1429327468486_0002_01_000001
2015-04-17 23:25:29,894 INFO org.apache.hadoop.yarn.server.resourcemanager.rmapp.RMAppImpl: application_1429327468486_0002 State change from FINISHING to FINISHED
2015-04-17 23:25:29,894 INFO org.apache.hadoop.yarn.server.resourcemanager.scheduler.SchedulerNode: Released container container_1429327468486_0002_01_000001 of capacity <memory:2048, vCores:1> on host k05n26.ccr.buffalo.edu:33870, which currently has 0 containers, <memory:0, vCores:0> used and <memory:8192, vCores:8> available, release resources=true
2015-04-17 23:25:29,894 INFO org.apache.hadoop.yarn.server.resourcemanager.scheduler.capacity.LeafQueue: default used=<memory:0, vCores:0> numContainers=0 user=u2 user-resources=<memory:0, vCores:0>
2015-04-17 23:25:29,894 INFO org.apache.hadoop.yarn.server.resourcemanager.RMAuditLogger: USER=u2	OPERATION=Application Finished - Succeeded	TARGET=RMAppManager	RESULT=SUCCESS	APPID=application_1429327468486_0002
2015-04-17 23:25:29,894 INFO org.apache.hadoop.yarn.server.resourcemanager.scheduler.capacity.LeafQueue: completedContainer container=Container: [ContainerId: container_1429327468486_0002_01_000001, NodeId: k05n26.ccr.buffalo.edu:33870, NodeHttpAddress: k05n26.ccr.buffalo.edu:8042, Resource: <memory:2048, vCores:1>, Priority: 0, Token: Token { kind: ContainerToken, service: 10.111.5.26:33870 }, ] queue=default: capacity=1.0, absoluteCapacity=1.0, usedResources=<memory:0, vCores:0>, usedCapacity=0.0, absoluteUsedCapacity=0.0, numApps=2, numContainers=0 cluster=<memory:8192, vCores:8>
2015-04-17 23:25:29,894 INFO org.apache.hadoop.yarn.server.resourcemanager.scheduler.capacity.ParentQueue: completedContainer queue=root usedCapacity=0.0 absoluteUsedCapacity=0.0 used=<memory:0, vCores:0> cluster=<memory:8192, vCores:8>
2015-04-17 23:25:29,894 INFO org.apache.hadoop.yarn.server.resourcemanager.scheduler.capacity.ParentQueue: Re-sorting completed queue: root.default stats: default: capacity=1.0, absoluteCapacity=1.0, usedResources=<memory:0, vCores:0>, usedCapacity=0.0, absoluteUsedCapacity=0.0, numApps=2, numContainers=0
2015-04-17 23:25:29,894 INFO org.apache.hadoop.yarn.server.resourcemanager.scheduler.capacity.CapacityScheduler: Application attempt appattempt_1429327468486_0002_000001 released container container_1429327468486_0002_01_000001 on node: host: k05n26.ccr.buffalo.edu:33870 #containers=0 available=8192 used=0 with event: FINISHED
2015-04-17 23:25:29,894 INFO org.apache.hadoop.yarn.server.resourcemanager.RMAppManager$ApplicationSummary: appId=application_1429327468486_0002,name=hw4.jar,user=u2,queue=default,state=FINISHED,trackingUrl=http://k05n26:8088/proxy/application_1429327468486_0002/jobhistory/job/job_1429327468486_0002,appMasterHost=k05n26,startTime=1429327501620,finishTime=1429327522961,finalStatus=SUCCEEDED
2015-04-17 23:25:29,894 INFO org.apache.hadoop.yarn.server.resourcemanager.amlauncher.AMLauncher: Cleaning master appattempt_1429327468486_0002_000001
2015-04-17 23:25:29,895 INFO org.apache.hadoop.yarn.server.resourcemanager.scheduler.capacity.CapacityScheduler: Application Attempt appattempt_1429327468486_0002_000001 is done. finalState=FINISHED
2015-04-17 23:25:29,895 INFO org.apache.hadoop.yarn.server.resourcemanager.scheduler.AppSchedulingInfo: Application application_1429327468486_0002 requests cleared
2015-04-17 23:25:29,895 INFO org.apache.hadoop.yarn.server.resourcemanager.scheduler.capacity.LeafQueue: Application application_1429327468486_0003 from user: u2 activated in queue: default
2015-04-17 23:25:29,895 INFO org.apache.hadoop.yarn.server.resourcemanager.scheduler.capacity.LeafQueue: Application removed - appId: application_1429327468486_0002 user: u2 queue: default #user-pending-applications: 0 #user-active-applications: 1 #queue-pending-applications: 0 #queue-active-applications: 1
2015-04-17 23:25:29,895 INFO org.apache.hadoop.yarn.server.resourcemanager.scheduler.capacity.ParentQueue: Application removed - appId: application_1429327468486_0002 user: u2 leaf-queue of parent: root #applications: 1
2015-04-17 23:25:30,895 INFO org.apache.hadoop.yarn.server.resourcemanager.rmcontainer.RMContainerImpl: container_1429327468486_0003_01_000001 Container Transitioned from NEW to ALLOCATED
2015-04-17 23:25:30,895 INFO org.apache.hadoop.yarn.server.resourcemanager.RMAuditLogger: USER=u2	OPERATION=AM Allocated Container	TARGET=SchedulerApp	RESULT=SUCCESS	APPID=application_1429327468486_0003	CONTAINERID=container_1429327468486_0003_01_000001
2015-04-17 23:25:30,895 INFO org.apache.hadoop.yarn.server.resourcemanager.scheduler.SchedulerNode: Assigned container container_1429327468486_0003_01_000001 of capacity <memory:2048, vCores:1> on host k05n26.ccr.buffalo.edu:33870, which has 1 containers, <memory:2048, vCores:1> used and <memory:6144, vCores:7> available after allocation
2015-04-17 23:25:30,896 INFO org.apache.hadoop.yarn.server.resourcemanager.scheduler.capacity.LeafQueue: assignedContainer application attempt=appattempt_1429327468486_0003_000001 container=Container: [ContainerId: container_1429327468486_0003_01_000001, NodeId: k05n26.ccr.buffalo.edu:33870, NodeHttpAddress: k05n26.ccr.buffalo.edu:8042, Resource: <memory:2048, vCores:1>, Priority: 0, Token: null, ] queue=default: capacity=1.0, absoluteCapacity=1.0, usedResources=<memory:0, vCores:0>, usedCapacity=0.0, absoluteUsedCapacity=0.0, numApps=1, numContainers=0 clusterResource=<memory:8192, vCores:8>
2015-04-17 23:25:30,896 INFO org.apache.hadoop.yarn.server.resourcemanager.scheduler.capacity.ParentQueue: Re-sorting assigned queue: root.default stats: default: capacity=1.0, absoluteCapacity=1.0, usedResources=<memory:2048, vCores:1>, usedCapacity=0.25, absoluteUsedCapacity=0.25, numApps=1, numContainers=1
2015-04-17 23:25:30,896 INFO org.apache.hadoop.yarn.server.resourcemanager.scheduler.capacity.ParentQueue: assignedContainer queue=root usedCapacity=0.25 absoluteUsedCapacity=0.25 used=<memory:2048, vCores:1> cluster=<memory:8192, vCores:8>
2015-04-17 23:25:30,896 INFO org.apache.hadoop.yarn.server.resourcemanager.security.NMTokenSecretManagerInRM: Sending NMToken for nodeId : k05n26.ccr.buffalo.edu:33870 for container : container_1429327468486_0003_01_000001
2015-04-17 23:25:30,897 INFO org.apache.hadoop.yarn.server.resourcemanager.rmcontainer.RMContainerImpl: container_1429327468486_0003_01_000001 Container Transitioned from ALLOCATED to ACQUIRED
2015-04-17 23:25:30,897 INFO org.apache.hadoop.yarn.server.resourcemanager.security.NMTokenSecretManagerInRM: Clear node set for appattempt_1429327468486_0003_000001
2015-04-17 23:25:30,897 INFO org.apache.hadoop.yarn.server.resourcemanager.rmapp.attempt.RMAppAttemptImpl: Storing attempt: AppId: application_1429327468486_0003 AttemptId: appattempt_1429327468486_0003_000001 MasterContainer: Container: [ContainerId: container_1429327468486_0003_01_000001, NodeId: k05n26.ccr.buffalo.edu:33870, NodeHttpAddress: k05n26.ccr.buffalo.edu:8042, Resource: <memory:2048, vCores:1>, Priority: 0, Token: Token { kind: ContainerToken, service: 10.111.5.26:33870 }, ]
2015-04-17 23:25:30,897 INFO org.apache.hadoop.yarn.server.resourcemanager.rmapp.attempt.RMAppAttemptImpl: appattempt_1429327468486_0003_000001 State change from SCHEDULED to ALLOCATED_SAVING
2015-04-17 23:25:30,897 INFO org.apache.hadoop.yarn.server.resourcemanager.rmapp.attempt.RMAppAttemptImpl: appattempt_1429327468486_0003_000001 State change from ALLOCATED_SAVING to ALLOCATED
2015-04-17 23:25:30,898 INFO org.apache.hadoop.yarn.server.resourcemanager.amlauncher.AMLauncher: Launching masterappattempt_1429327468486_0003_000001
2015-04-17 23:25:30,899 INFO org.apache.hadoop.yarn.server.resourcemanager.amlauncher.AMLauncher: Setting up container Container: [ContainerId: container_1429327468486_0003_01_000001, NodeId: k05n26.ccr.buffalo.edu:33870, NodeHttpAddress: k05n26.ccr.buffalo.edu:8042, Resource: <memory:2048, vCores:1>, Priority: 0, Token: Token { kind: ContainerToken, service: 10.111.5.26:33870 }, ] for AM appattempt_1429327468486_0003_000001
2015-04-17 23:25:30,899 INFO org.apache.hadoop.yarn.server.resourcemanager.amlauncher.AMLauncher: Command to launch container container_1429327468486_0003_01_000001 : $JAVA_HOME/bin/java -Dlog4j.configuration=container-log4j.properties -Dyarn.app.container.log.dir=<LOG_DIR> -Dyarn.app.container.log.filesize=0 -Dhadoop.root.logger=INFO,CLA  -Xmx1024m org.apache.hadoop.mapreduce.v2.app.MRAppMaster 1><LOG_DIR>/stdout 2><LOG_DIR>/stderr 
2015-04-17 23:25:30,906 INFO org.apache.hadoop.yarn.server.resourcemanager.amlauncher.AMLauncher: Done launching container Container: [ContainerId: container_1429327468486_0003_01_000001, NodeId: k05n26.ccr.buffalo.edu:33870, NodeHttpAddress: k05n26.ccr.buffalo.edu:8042, Resource: <memory:2048, vCores:1>, Priority: 0, Token: Token { kind: ContainerToken, service: 10.111.5.26:33870 }, ] for AM appattempt_1429327468486_0003_000001
2015-04-17 23:25:30,907 INFO org.apache.hadoop.yarn.server.resourcemanager.rmapp.attempt.RMAppAttemptImpl: appattempt_1429327468486_0003_000001 State change from ALLOCATED to LAUNCHED
2015-04-17 23:25:31,901 INFO org.apache.hadoop.yarn.server.resourcemanager.rmcontainer.RMContainerImpl: container_1429327468486_0003_01_000001 Container Transitioned from ACQUIRED to RUNNING
2015-04-17 23:25:35,762 INFO SecurityLogger.org.apache.hadoop.ipc.Server: Auth successful for appattempt_1429327468486_0003_000001 (auth:SIMPLE)
2015-04-17 23:25:35,764 INFO org.apache.hadoop.yarn.server.resourcemanager.ApplicationMasterService: AM registration appattempt_1429327468486_0003_000001
2015-04-17 23:25:35,765 INFO org.apache.hadoop.yarn.server.resourcemanager.RMAuditLogger: USER=u2	IP=10.111.5.26	OPERATION=Register App Master	TARGET=ApplicationMasterService	RESULT=SUCCESS	APPID=application_1429327468486_0003	APPATTEMPTID=appattempt_1429327468486_0003_000001
2015-04-17 23:25:35,766 INFO org.apache.hadoop.yarn.server.resourcemanager.rmapp.attempt.RMAppAttemptImpl: appattempt_1429327468486_0003_000001 State change from LAUNCHED to RUNNING
2015-04-17 23:25:35,766 INFO org.apache.hadoop.yarn.server.resourcemanager.rmapp.RMAppImpl: application_1429327468486_0003 State change from ACCEPTED to RUNNING
2015-04-17 23:25:36,910 INFO org.apache.hadoop.yarn.server.resourcemanager.rmcontainer.RMContainerImpl: container_1429327468486_0003_01_000002 Container Transitioned from NEW to ALLOCATED
2015-04-17 23:25:36,910 INFO org.apache.hadoop.yarn.server.resourcemanager.RMAuditLogger: USER=u2	OPERATION=AM Allocated Container	TARGET=SchedulerApp	RESULT=SUCCESS	APPID=application_1429327468486_0003	CONTAINERID=container_1429327468486_0003_01_000002
2015-04-17 23:25:36,910 INFO org.apache.hadoop.yarn.server.resourcemanager.scheduler.SchedulerNode: Assigned container container_1429327468486_0003_01_000002 of capacity <memory:1024, vCores:1> on host k05n26.ccr.buffalo.edu:33870, which has 2 containers, <memory:3072, vCores:2> used and <memory:5120, vCores:6> available after allocation
2015-04-17 23:25:36,910 INFO org.apache.hadoop.yarn.server.resourcemanager.scheduler.capacity.LeafQueue: assignedContainer application attempt=appattempt_1429327468486_0003_000001 container=Container: [ContainerId: container_1429327468486_0003_01_000002, NodeId: k05n26.ccr.buffalo.edu:33870, NodeHttpAddress: k05n26.ccr.buffalo.edu:8042, Resource: <memory:1024, vCores:1>, Priority: 20, Token: null, ] queue=default: capacity=1.0, absoluteCapacity=1.0, usedResources=<memory:2048, vCores:1>, usedCapacity=0.25, absoluteUsedCapacity=0.25, numApps=1, numContainers=1 clusterResource=<memory:8192, vCores:8>
2015-04-17 23:25:36,910 INFO org.apache.hadoop.yarn.server.resourcemanager.scheduler.capacity.ParentQueue: Re-sorting assigned queue: root.default stats: default: capacity=1.0, absoluteCapacity=1.0, usedResources=<memory:3072, vCores:2>, usedCapacity=0.375, absoluteUsedCapacity=0.375, numApps=1, numContainers=2
2015-04-17 23:25:36,910 INFO org.apache.hadoop.yarn.server.resourcemanager.scheduler.capacity.ParentQueue: assignedContainer queue=root usedCapacity=0.375 absoluteUsedCapacity=0.375 used=<memory:3072, vCores:2> cluster=<memory:8192, vCores:8>
2015-04-17 23:25:37,803 INFO org.apache.hadoop.yarn.server.resourcemanager.security.NMTokenSecretManagerInRM: Sending NMToken for nodeId : k05n26.ccr.buffalo.edu:33870 for container : container_1429327468486_0003_01_000002
2015-04-17 23:25:37,804 INFO org.apache.hadoop.yarn.server.resourcemanager.rmcontainer.RMContainerImpl: container_1429327468486_0003_01_000002 Container Transitioned from ALLOCATED to ACQUIRED
2015-04-17 23:25:38,814 INFO org.apache.hadoop.yarn.server.resourcemanager.scheduler.AppSchedulingInfo: checking for deactivate... 
2015-04-17 23:25:38,913 INFO org.apache.hadoop.yarn.server.resourcemanager.rmcontainer.RMContainerImpl: container_1429327468486_0003_01_000002 Container Transitioned from ACQUIRED to RUNNING
2015-04-17 23:25:41,607 INFO org.apache.hadoop.yarn.server.resourcemanager.rmcontainer.RMContainerImpl: container_1429327468486_0003_01_000002 Container Transitioned from RUNNING to COMPLETED
2015-04-17 23:25:41,607 INFO org.apache.hadoop.yarn.server.resourcemanager.scheduler.common.fica.FiCaSchedulerApp: Completed container: container_1429327468486_0003_01_000002 in state: COMPLETED event:FINISHED
2015-04-17 23:25:41,607 INFO org.apache.hadoop.yarn.server.resourcemanager.RMAuditLogger: USER=u2	OPERATION=AM Released Container	TARGET=SchedulerApp	RESULT=SUCCESS	APPID=application_1429327468486_0003	CONTAINERID=container_1429327468486_0003_01_000002
2015-04-17 23:25:41,607 INFO org.apache.hadoop.yarn.server.resourcemanager.scheduler.SchedulerNode: Released container container_1429327468486_0003_01_000002 of capacity <memory:1024, vCores:1> on host k05n26.ccr.buffalo.edu:33870, which currently has 1 containers, <memory:2048, vCores:1> used and <memory:6144, vCores:7> available, release resources=true
2015-04-17 23:25:41,607 INFO org.apache.hadoop.yarn.server.resourcemanager.scheduler.capacity.LeafQueue: default used=<memory:2048, vCores:1> numContainers=1 user=u2 user-resources=<memory:2048, vCores:1>
2015-04-17 23:25:41,607 INFO org.apache.hadoop.yarn.server.resourcemanager.scheduler.capacity.LeafQueue: completedContainer container=Container: [ContainerId: container_1429327468486_0003_01_000002, NodeId: k05n26.ccr.buffalo.edu:33870, NodeHttpAddress: k05n26.ccr.buffalo.edu:8042, Resource: <memory:1024, vCores:1>, Priority: 20, Token: Token { kind: ContainerToken, service: 10.111.5.26:33870 }, ] queue=default: capacity=1.0, absoluteCapacity=1.0, usedResources=<memory:2048, vCores:1>, usedCapacity=0.25, absoluteUsedCapacity=0.25, numApps=1, numContainers=1 cluster=<memory:8192, vCores:8>
2015-04-17 23:25:41,607 INFO org.apache.hadoop.yarn.server.resourcemanager.scheduler.capacity.ParentQueue: completedContainer queue=root usedCapacity=0.25 absoluteUsedCapacity=0.25 used=<memory:2048, vCores:1> cluster=<memory:8192, vCores:8>
2015-04-17 23:25:41,607 INFO org.apache.hadoop.yarn.server.resourcemanager.scheduler.capacity.ParentQueue: Re-sorting completed queue: root.default stats: default: capacity=1.0, absoluteCapacity=1.0, usedResources=<memory:2048, vCores:1>, usedCapacity=0.25, absoluteUsedCapacity=0.25, numApps=1, numContainers=1
2015-04-17 23:25:41,608 INFO org.apache.hadoop.yarn.server.resourcemanager.scheduler.capacity.CapacityScheduler: Application attempt appattempt_1429327468486_0003_000001 released container container_1429327468486_0003_01_000002 on node: host: k05n26.ccr.buffalo.edu:33870 #containers=1 available=6144 used=2048 with event: FINISHED
2015-04-17 23:25:42,608 INFO org.apache.hadoop.yarn.server.resourcemanager.rmcontainer.RMContainerImpl: container_1429327468486_0003_01_000003 Container Transitioned from NEW to ALLOCATED
2015-04-17 23:25:42,608 INFO org.apache.hadoop.yarn.server.resourcemanager.RMAuditLogger: USER=u2	OPERATION=AM Allocated Container	TARGET=SchedulerApp	RESULT=SUCCESS	APPID=application_1429327468486_0003	CONTAINERID=container_1429327468486_0003_01_000003
2015-04-17 23:25:42,608 INFO org.apache.hadoop.yarn.server.resourcemanager.scheduler.SchedulerNode: Assigned container container_1429327468486_0003_01_000003 of capacity <memory:1024, vCores:1> on host k05n26.ccr.buffalo.edu:33870, which has 2 containers, <memory:3072, vCores:2> used and <memory:5120, vCores:6> available after allocation
2015-04-17 23:25:42,608 INFO org.apache.hadoop.yarn.server.resourcemanager.scheduler.capacity.LeafQueue: assignedContainer application attempt=appattempt_1429327468486_0003_000001 container=Container: [ContainerId: container_1429327468486_0003_01_000003, NodeId: k05n26.ccr.buffalo.edu:33870, NodeHttpAddress: k05n26.ccr.buffalo.edu:8042, Resource: <memory:1024, vCores:1>, Priority: 10, Token: null, ] queue=default: capacity=1.0, absoluteCapacity=1.0, usedResources=<memory:2048, vCores:1>, usedCapacity=0.25, absoluteUsedCapacity=0.25, numApps=1, numContainers=1 clusterResource=<memory:8192, vCores:8>
2015-04-17 23:25:42,608 INFO org.apache.hadoop.yarn.server.resourcemanager.scheduler.capacity.ParentQueue: Re-sorting assigned queue: root.default stats: default: capacity=1.0, absoluteCapacity=1.0, usedResources=<memory:3072, vCores:2>, usedCapacity=0.375, absoluteUsedCapacity=0.375, numApps=1, numContainers=2
2015-04-17 23:25:42,608 INFO org.apache.hadoop.yarn.server.resourcemanager.scheduler.capacity.ParentQueue: assignedContainer queue=root usedCapacity=0.375 absoluteUsedCapacity=0.375 used=<memory:3072, vCores:2> cluster=<memory:8192, vCores:8>
2015-04-17 23:25:42,826 INFO org.apache.hadoop.yarn.server.resourcemanager.rmcontainer.RMContainerImpl: container_1429327468486_0003_01_000003 Container Transitioned from ALLOCATED to ACQUIRED
2015-04-17 23:25:43,610 INFO org.apache.hadoop.yarn.server.resourcemanager.rmcontainer.RMContainerImpl: container_1429327468486_0003_01_000003 Container Transitioned from ACQUIRED to RUNNING
2015-04-17 23:25:43,829 INFO org.apache.hadoop.yarn.server.resourcemanager.scheduler.AppSchedulingInfo: checking for deactivate... 
2015-04-17 23:25:45,700 INFO org.apache.hadoop.yarn.server.resourcemanager.rmapp.attempt.RMAppAttemptImpl: Updating application attempt appattempt_1429327468486_0003_000001 with final state: FINISHING, and exit status: -1000
2015-04-17 23:25:45,700 INFO org.apache.hadoop.yarn.server.resourcemanager.rmapp.attempt.RMAppAttemptImpl: appattempt_1429327468486_0003_000001 State change from RUNNING to FINAL_SAVING
2015-04-17 23:25:45,700 INFO org.apache.hadoop.yarn.server.resourcemanager.rmapp.RMAppImpl: Updating application application_1429327468486_0003 with final state: FINISHING
2015-04-17 23:25:45,700 INFO org.apache.hadoop.yarn.server.resourcemanager.rmapp.RMAppImpl: application_1429327468486_0003 State change from RUNNING to FINAL_SAVING
2015-04-17 23:25:45,700 INFO org.apache.hadoop.yarn.server.resourcemanager.recovery.RMStateStore: Updating info for app: application_1429327468486_0003
2015-04-17 23:25:45,700 INFO org.apache.hadoop.yarn.server.resourcemanager.rmapp.attempt.RMAppAttemptImpl: appattempt_1429327468486_0003_000001 State change from FINAL_SAVING to FINISHING
2015-04-17 23:25:45,701 INFO org.apache.hadoop.yarn.server.resourcemanager.rmapp.RMAppImpl: application_1429327468486_0003 State change from FINAL_SAVING to FINISHING
2015-04-17 23:25:46,626 INFO org.apache.hadoop.yarn.server.resourcemanager.rmcontainer.RMContainerImpl: container_1429327468486_0003_01_000003 Container Transitioned from RUNNING to COMPLETED
2015-04-17 23:25:46,626 INFO org.apache.hadoop.yarn.server.resourcemanager.scheduler.common.fica.FiCaSchedulerApp: Completed container: container_1429327468486_0003_01_000003 in state: COMPLETED event:FINISHED
2015-04-17 23:25:46,627 INFO org.apache.hadoop.yarn.server.resourcemanager.RMAuditLogger: USER=u2	OPERATION=AM Released Container	TARGET=SchedulerApp	RESULT=SUCCESS	APPID=application_1429327468486_0003	CONTAINERID=container_1429327468486_0003_01_000003
2015-04-17 23:25:46,627 INFO org.apache.hadoop.yarn.server.resourcemanager.scheduler.SchedulerNode: Released container container_1429327468486_0003_01_000003 of capacity <memory:1024, vCores:1> on host k05n26.ccr.buffalo.edu:33870, which currently has 1 containers, <memory:2048, vCores:1> used and <memory:6144, vCores:7> available, release resources=true
2015-04-17 23:25:46,627 INFO org.apache.hadoop.yarn.server.resourcemanager.scheduler.capacity.LeafQueue: default used=<memory:2048, vCores:1> numContainers=1 user=u2 user-resources=<memory:2048, vCores:1>
2015-04-17 23:25:46,627 INFO org.apache.hadoop.yarn.server.resourcemanager.scheduler.capacity.LeafQueue: completedContainer container=Container: [ContainerId: container_1429327468486_0003_01_000003, NodeId: k05n26.ccr.buffalo.edu:33870, NodeHttpAddress: k05n26.ccr.buffalo.edu:8042, Resource: <memory:1024, vCores:1>, Priority: 10, Token: Token { kind: ContainerToken, service: 10.111.5.26:33870 }, ] queue=default: capacity=1.0, absoluteCapacity=1.0, usedResources=<memory:2048, vCores:1>, usedCapacity=0.25, absoluteUsedCapacity=0.25, numApps=1, numContainers=1 cluster=<memory:8192, vCores:8>
2015-04-17 23:25:46,627 INFO org.apache.hadoop.yarn.server.resourcemanager.scheduler.capacity.ParentQueue: completedContainer queue=root usedCapacity=0.25 absoluteUsedCapacity=0.25 used=<memory:2048, vCores:1> cluster=<memory:8192, vCores:8>
2015-04-17 23:25:46,627 INFO org.apache.hadoop.yarn.server.resourcemanager.scheduler.capacity.ParentQueue: Re-sorting completed queue: root.default stats: default: capacity=1.0, absoluteCapacity=1.0, usedResources=<memory:2048, vCores:1>, usedCapacity=0.25, absoluteUsedCapacity=0.25, numApps=1, numContainers=1
2015-04-17 23:25:46,627 INFO org.apache.hadoop.yarn.server.resourcemanager.scheduler.capacity.CapacityScheduler: Application attempt appattempt_1429327468486_0003_000001 released container container_1429327468486_0003_01_000003 on node: host: k05n26.ccr.buffalo.edu:33870 #containers=1 available=6144 used=2048 with event: FINISHED
2015-04-17 23:25:52,636 INFO org.apache.hadoop.yarn.server.resourcemanager.rmcontainer.RMContainerImpl: container_1429327468486_0003_01_000001 Container Transitioned from RUNNING to COMPLETED
2015-04-17 23:25:52,636 INFO org.apache.hadoop.yarn.server.resourcemanager.ApplicationMasterService: Unregistering app attempt : appattempt_1429327468486_0003_000001
2015-04-17 23:25:52,636 INFO org.apache.hadoop.yarn.server.resourcemanager.scheduler.common.fica.FiCaSchedulerApp: Completed container: container_1429327468486_0003_01_000001 in state: COMPLETED event:FINISHED
2015-04-17 23:25:52,637 INFO org.apache.hadoop.yarn.server.resourcemanager.rmapp.attempt.RMAppAttemptImpl: appattempt_1429327468486_0003_000001 State change from FINISHING to FINISHED
2015-04-17 23:25:52,637 INFO org.apache.hadoop.yarn.server.resourcemanager.RMAuditLogger: USER=u2	OPERATION=AM Released Container	TARGET=SchedulerApp	RESULT=SUCCESS	APPID=application_1429327468486_0003	CONTAINERID=container_1429327468486_0003_01_000001
2015-04-17 23:25:52,637 INFO org.apache.hadoop.yarn.server.resourcemanager.rmapp.RMAppImpl: application_1429327468486_0003 State change from FINISHING to FINISHED
2015-04-17 23:25:52,637 INFO org.apache.hadoop.yarn.server.resourcemanager.scheduler.SchedulerNode: Released container container_1429327468486_0003_01_000001 of capacity <memory:2048, vCores:1> on host k05n26.ccr.buffalo.edu:33870, which currently has 0 containers, <memory:0, vCores:0> used and <memory:8192, vCores:8> available, release resources=true
2015-04-17 23:25:52,637 INFO org.apache.hadoop.yarn.server.resourcemanager.scheduler.capacity.LeafQueue: default used=<memory:0, vCores:0> numContainers=0 user=u2 user-resources=<memory:0, vCores:0>
2015-04-17 23:25:52,637 INFO org.apache.hadoop.yarn.server.resourcemanager.RMAuditLogger: USER=u2	OPERATION=Application Finished - Succeeded	TARGET=RMAppManager	RESULT=SUCCESS	APPID=application_1429327468486_0003
2015-04-17 23:25:52,637 INFO org.apache.hadoop.yarn.server.resourcemanager.scheduler.capacity.LeafQueue: completedContainer container=Container: [ContainerId: container_1429327468486_0003_01_000001, NodeId: k05n26.ccr.buffalo.edu:33870, NodeHttpAddress: k05n26.ccr.buffalo.edu:8042, Resource: <memory:2048, vCores:1>, Priority: 0, Token: Token { kind: ContainerToken, service: 10.111.5.26:33870 }, ] queue=default: capacity=1.0, absoluteCapacity=1.0, usedResources=<memory:0, vCores:0>, usedCapacity=0.0, absoluteUsedCapacity=0.0, numApps=1, numContainers=0 cluster=<memory:8192, vCores:8>
2015-04-17 23:25:52,637 INFO org.apache.hadoop.yarn.server.resourcemanager.scheduler.capacity.ParentQueue: completedContainer queue=root usedCapacity=0.0 absoluteUsedCapacity=0.0 used=<memory:0, vCores:0> cluster=<memory:8192, vCores:8>
2015-04-17 23:25:52,637 INFO org.apache.hadoop.yarn.server.resourcemanager.scheduler.capacity.ParentQueue: Re-sorting completed queue: root.default stats: default: capacity=1.0, absoluteCapacity=1.0, usedResources=<memory:0, vCores:0>, usedCapacity=0.0, absoluteUsedCapacity=0.0, numApps=1, numContainers=0
2015-04-17 23:25:52,637 INFO org.apache.hadoop.yarn.server.resourcemanager.amlauncher.AMLauncher: Cleaning master appattempt_1429327468486_0003_000001
2015-04-17 23:25:52,638 INFO org.apache.hadoop.yarn.server.resourcemanager.RMAppManager$ApplicationSummary: appId=application_1429327468486_0003,name=hw4.jar,user=u2,queue=default,state=FINISHED,trackingUrl=http://k05n26:8088/proxy/application_1429327468486_0003/jobhistory/job/job_1429327468486_0003,appMasterHost=k05n26,startTime=1429327525494,finishTime=1429327545700,finalStatus=SUCCEEDED
2015-04-17 23:25:52,637 INFO org.apache.hadoop.yarn.server.resourcemanager.scheduler.capacity.CapacityScheduler: Application attempt appattempt_1429327468486_0003_000001 released container container_1429327468486_0003_01_000001 on node: host: k05n26.ccr.buffalo.edu:33870 #containers=0 available=8192 used=0 with event: FINISHED
2015-04-17 23:25:52,638 INFO org.apache.hadoop.yarn.server.resourcemanager.scheduler.capacity.CapacityScheduler: Application Attempt appattempt_1429327468486_0003_000001 is done. finalState=FINISHED
2015-04-17 23:25:52,638 INFO org.apache.hadoop.yarn.server.resourcemanager.scheduler.AppSchedulingInfo: Application application_1429327468486_0003 requests cleared
2015-04-17 23:25:52,638 INFO org.apache.hadoop.yarn.server.resourcemanager.scheduler.capacity.LeafQueue: Application removed - appId: application_1429327468486_0003 user: u2 queue: default #user-pending-applications: 0 #user-active-applications: 0 #queue-pending-applications: 0 #queue-active-applications: 0
2015-04-17 23:25:52,638 INFO org.apache.hadoop.yarn.server.resourcemanager.scheduler.capacity.ParentQueue: Application removed - appId: application_1429327468486_0003 user: u2 leaf-queue of parent: root #applications: 0
2015-04-17 23:26:34,043 ERROR org.apache.hadoop.yarn.server.resourcemanager.ResourceManager: RECEIVED SIGNAL 15: SIGTERM
2015-04-17 23:26:34,047 INFO org.mortbay.log: Stopped HttpServer2$SelectChannelConnectorWithSafeStartup@k05n26:8088
2015-04-17 23:26:34,147 INFO org.apache.hadoop.ipc.Server: Stopping server on 8032
2015-04-17 23:26:34,148 INFO org.apache.hadoop.ipc.Server: Stopping IPC Server listener on 8032
2015-04-17 23:26:34,148 INFO org.apache.hadoop.ipc.Server: Stopping server on 8033
2015-04-17 23:26:34,148 INFO org.apache.hadoop.ipc.Server: Stopping IPC Server Responder
2015-04-17 23:26:34,148 INFO org.apache.hadoop.ipc.Server: Stopping IPC Server listener on 8033
2015-04-17 23:26:34,148 INFO org.apache.hadoop.ipc.Server: Stopping IPC Server Responder
2015-04-17 23:26:34,148 INFO org.apache.hadoop.yarn.server.resourcemanager.ResourceManager: Transitioning to standby state
2015-04-17 23:26:34,148 INFO org.apache.hadoop.metrics2.impl.MetricsSystemImpl: Stopping ResourceManager metrics system...
2015-04-17 23:26:34,149 INFO org.apache.hadoop.metrics2.impl.MetricsSystemImpl: ResourceManager metrics system stopped.
2015-04-17 23:26:34,149 INFO org.apache.hadoop.metrics2.impl.MetricsSystemImpl: ResourceManager metrics system shutdown complete.
2015-04-17 23:26:34,149 INFO org.apache.hadoop.yarn.event.AsyncDispatcher: AsyncDispatcher is draining to stop, igonring any new events.
2015-04-17 23:26:34,150 WARN org.apache.hadoop.yarn.server.resourcemanager.amlauncher.ApplicationMasterLauncher: org.apache.hadoop.yarn.server.resourcemanager.amlauncher.ApplicationMasterLauncher$LauncherThread interrupted. Returning.
2015-04-17 23:26:34,151 INFO org.apache.hadoop.ipc.Server: Stopping server on 8030
2015-04-17 23:26:34,152 INFO org.apache.hadoop.ipc.Server: Stopping IPC Server listener on 8030
2015-04-17 23:26:34,152 INFO org.apache.hadoop.ipc.Server: Stopping server on 8031
2015-04-17 23:26:34,152 INFO org.apache.hadoop.ipc.Server: Stopping IPC Server Responder
2015-04-17 23:26:34,154 INFO org.apache.hadoop.ipc.Server: Stopping IPC Server listener on 8031
2015-04-17 23:26:34,154 ERROR org.apache.hadoop.yarn.server.resourcemanager.ResourceManager: Returning, interrupted : java.lang.InterruptedException
2015-04-17 23:26:34,155 INFO org.apache.hadoop.yarn.event.AsyncDispatcher: AsyncDispatcher is draining to stop, igonring any new events.
2015-04-17 23:26:34,156 INFO org.apache.hadoop.yarn.util.AbstractLivelinessMonitor: NMLivelinessMonitor thread interrupted
2015-04-17 23:26:34,156 INFO org.apache.hadoop.yarn.event.AsyncDispatcher: AsyncDispatcher is draining to stop, igonring any new events.
2015-04-17 23:26:34,156 INFO org.apache.hadoop.ipc.Server: Stopping IPC Server Responder
2015-04-17 23:26:34,156 INFO org.apache.hadoop.yarn.event.AsyncDispatcher: AsyncDispatcher is draining to stop, igonring any new events.
2015-04-17 23:26:34,156 INFO org.apache.hadoop.yarn.event.AsyncDispatcher: AsyncDispatcher is draining to stop, igonring any new events.
2015-04-17 23:26:34,157 INFO org.apache.hadoop.yarn.event.AsyncDispatcher: AsyncDispatcher is draining to stop, igonring any new events.
2015-04-17 23:26:34,157 INFO org.apache.hadoop.yarn.event.AsyncDispatcher: AsyncDispatcher is draining to stop, igonring any new events.
2015-04-17 23:26:34,157 INFO org.apache.hadoop.yarn.event.AsyncDispatcher: AsyncDispatcher is draining to stop, igonring any new events.
2015-04-17 23:26:34,158 INFO org.apache.hadoop.yarn.event.AsyncDispatcher: AsyncDispatcher is draining to stop, igonring any new events.
2015-04-17 23:26:34,165 INFO org.apache.hadoop.yarn.event.AsyncDispatcher: AsyncDispatcher is draining to stop, igonring any new events.
2015-04-17 23:26:34,165 INFO org.apache.hadoop.yarn.event.AsyncDispatcher: AsyncDispatcher is draining to stop, igonring any new events.
2015-04-17 23:26:34,165 INFO org.apache.hadoop.yarn.util.AbstractLivelinessMonitor: AMLivelinessMonitor thread interrupted
2015-04-17 23:26:34,165 INFO org.apache.hadoop.yarn.util.AbstractLivelinessMonitor: AMLivelinessMonitor thread interrupted
2015-04-17 23:26:34,165 INFO org.apache.hadoop.yarn.util.AbstractLivelinessMonitor: org.apache.hadoop.yarn.server.resourcemanager.rmcontainer.ContainerAllocationExpirer thread interrupted
2015-04-17 23:26:34,165 ERROR org.apache.hadoop.security.token.delegation.AbstractDelegationTokenSecretManager: ExpiredTokenRemover received java.lang.InterruptedException: sleep interrupted
2015-04-17 23:26:34,166 INFO org.apache.hadoop.yarn.server.resourcemanager.ResourceManager: Transitioned to standby state
2015-04-17 23:26:34,166 INFO org.apache.hadoop.yarn.server.resourcemanager.ResourceManager: SHUTDOWN_MSG: 
/************************************************************
SHUTDOWN_MSG: Shutting down ResourceManager at k05n26/10.111.5.26
************************************************************/
