2015-04-10 19:28:38,725 INFO org.apache.hadoop.yarn.server.resourcemanager.ResourceManager: STARTUP_MSG: 
/************************************************************
STARTUP_MSG: Starting ResourceManager
STARTUP_MSG:   host = k08n41s01/10.111.8.41
STARTUP_MSG:   args = []
STARTUP_MSG:   version = 2.5.1
STARTUP_MSG:   build = https://git-wip-us.apache.org/repos/asf/hadoop.git -r 2e18d179e4a8065b6a9f29cf2de9451891265cce; compiled by 'jenkins' on 2014-09-05T23:11Z
STARTUP_MSG:   java = 1.6.0_22
************************************************************/
2015-04-10 19:28:38,733 INFO org.apache.hadoop.yarn.server.resourcemanager.ResourceManager: registered UNIX signal handlers for [TERM, HUP, INT]
2015-04-10 19:28:38,937 INFO org.apache.hadoop.conf.Configuration: found resource core-site.xml at file:/gpfs/courses/cse587/spring2015/students/u2/hw4/Uploader/config-3674693/core-site.xml
2015-04-10 19:28:39,044 WARN org.apache.hadoop.util.NativeCodeLoader: Unable to load native-hadoop library for your platform... using builtin-java classes where applicable
2015-04-10 19:28:39,046 INFO org.apache.hadoop.security.Groups: clearing userToGroupsMap cache
2015-04-10 19:28:39,053 INFO org.apache.hadoop.conf.Configuration: found resource yarn-site.xml at file:/gpfs/courses/cse587/spring2015/students/u2/hw4/Uploader/config-3674693/yarn-site.xml
2015-04-10 19:28:39,110 WARN org.apache.hadoop.conf.Configuration: java.io.BufferedInputStream@2dafae45:an attempt to override final parameter: yarn.resourcemanager.hostname;  Ignoring.
2015-04-10 19:28:39,114 INFO org.apache.hadoop.yarn.event.AsyncDispatcher: Registering class org.apache.hadoop.yarn.server.resourcemanager.RMFatalEventType for class org.apache.hadoop.yarn.server.resourcemanager.ResourceManager$RMFatalEventDispatcher
2015-04-10 19:28:39,579 INFO org.apache.hadoop.yarn.server.resourcemanager.security.NMTokenSecretManagerInRM: NMTokenKeyRollingInterval: 86400000ms and NMTokenKeyActivationDelay: 900000ms
2015-04-10 19:28:39,583 INFO org.apache.hadoop.yarn.server.resourcemanager.security.RMContainerTokenSecretManager: ContainerTokenKeyRollingInterval: 86400000ms and ContainerTokenKeyActivationDelay: 900000ms
2015-04-10 19:28:39,586 INFO org.apache.hadoop.yarn.server.resourcemanager.security.AMRMTokenSecretManager: Rolling master-key for amrm-tokens
2015-04-10 19:28:39,609 INFO org.apache.hadoop.yarn.event.AsyncDispatcher: Registering class org.apache.hadoop.yarn.server.resourcemanager.recovery.RMStateStoreEventType for class org.apache.hadoop.yarn.server.resourcemanager.recovery.RMStateStore$ForwardingEventHandler
2015-04-10 19:28:39,770 INFO org.apache.hadoop.yarn.event.AsyncDispatcher: Registering class org.apache.hadoop.yarn.server.resourcemanager.NodesListManagerEventType for class org.apache.hadoop.yarn.server.resourcemanager.NodesListManager
2015-04-10 19:28:39,770 INFO org.apache.hadoop.yarn.server.resourcemanager.ResourceManager: Using Scheduler: org.apache.hadoop.yarn.server.resourcemanager.scheduler.capacity.CapacityScheduler
2015-04-10 19:28:39,803 INFO org.apache.hadoop.yarn.event.AsyncDispatcher: Registering class org.apache.hadoop.yarn.server.resourcemanager.scheduler.event.SchedulerEventType for class org.apache.hadoop.yarn.server.resourcemanager.ResourceManager$SchedulerEventDispatcher
2015-04-10 19:28:39,804 INFO org.apache.hadoop.yarn.event.AsyncDispatcher: Registering class org.apache.hadoop.yarn.server.resourcemanager.rmapp.RMAppEventType for class org.apache.hadoop.yarn.server.resourcemanager.ResourceManager$ApplicationEventDispatcher
2015-04-10 19:28:39,805 INFO org.apache.hadoop.yarn.event.AsyncDispatcher: Registering class org.apache.hadoop.yarn.server.resourcemanager.rmapp.attempt.RMAppAttemptEventType for class org.apache.hadoop.yarn.server.resourcemanager.ResourceManager$ApplicationAttemptEventDispatcher
2015-04-10 19:28:39,806 INFO org.apache.hadoop.yarn.event.AsyncDispatcher: Registering class org.apache.hadoop.yarn.server.resourcemanager.rmnode.RMNodeEventType for class org.apache.hadoop.yarn.server.resourcemanager.ResourceManager$NodeEventDispatcher
2015-04-10 19:28:39,878 INFO org.apache.hadoop.metrics2.impl.MetricsConfig: loaded properties from hadoop-metrics2.properties
2015-04-10 19:28:39,929 INFO org.apache.hadoop.metrics2.impl.MetricsSystemImpl: Scheduled snapshot period at 10 second(s).
2015-04-10 19:28:39,930 INFO org.apache.hadoop.metrics2.impl.MetricsSystemImpl: ResourceManager metrics system started
2015-04-10 19:28:39,981 INFO org.apache.hadoop.yarn.event.AsyncDispatcher: Registering class org.apache.hadoop.yarn.server.resourcemanager.RMAppManagerEventType for class org.apache.hadoop.yarn.server.resourcemanager.RMAppManager
2015-04-10 19:28:39,989 INFO org.apache.hadoop.yarn.event.AsyncDispatcher: Registering class org.apache.hadoop.yarn.server.resourcemanager.amlauncher.AMLauncherEventType for class org.apache.hadoop.yarn.server.resourcemanager.amlauncher.ApplicationMasterLauncher
2015-04-10 19:28:39,991 INFO org.apache.hadoop.yarn.server.resourcemanager.RMNMInfo: Registered RMNMInfo MBean
2015-04-10 19:28:39,994 INFO org.apache.hadoop.yarn.event.AsyncDispatcher: Registering class org.apache.hadoop.yarn.server.resourcemanager.ahs.WritingHistoryEventType for class org.apache.hadoop.yarn.server.resourcemanager.ahs.RMApplicationHistoryWriter$ForwardingEventHandler
2015-04-10 19:28:39,994 INFO org.apache.hadoop.yarn.event.AsyncDispatcher: Registering class org.apache.hadoop.yarn.server.resourcemanager.ahs.WritingHistoryEventType for class org.apache.hadoop.yarn.server.resourcemanager.ahs.RMApplicationHistoryWriter$ForwardingEventHandler
2015-04-10 19:28:39,994 INFO org.apache.hadoop.yarn.event.AsyncDispatcher: Registering class org.apache.hadoop.yarn.server.resourcemanager.ahs.WritingHistoryEventType for class org.apache.hadoop.yarn.server.resourcemanager.ahs.RMApplicationHistoryWriter$ForwardingEventHandler
2015-04-10 19:28:39,994 INFO org.apache.hadoop.yarn.event.AsyncDispatcher: Registering class org.apache.hadoop.yarn.server.resourcemanager.ahs.WritingHistoryEventType for class org.apache.hadoop.yarn.server.resourcemanager.ahs.RMApplicationHistoryWriter$ForwardingEventHandler
2015-04-10 19:28:39,994 INFO org.apache.hadoop.yarn.event.AsyncDispatcher: Registering class org.apache.hadoop.yarn.server.resourcemanager.ahs.WritingHistoryEventType for class org.apache.hadoop.yarn.server.resourcemanager.ahs.RMApplicationHistoryWriter$ForwardingEventHandler
2015-04-10 19:28:39,994 INFO org.apache.hadoop.yarn.event.AsyncDispatcher: Registering class org.apache.hadoop.yarn.server.resourcemanager.ahs.WritingHistoryEventType for class org.apache.hadoop.yarn.server.resourcemanager.ahs.RMApplicationHistoryWriter$ForwardingEventHandler
2015-04-10 19:28:39,994 INFO org.apache.hadoop.yarn.event.AsyncDispatcher: Registering class org.apache.hadoop.yarn.server.resourcemanager.ahs.WritingHistoryEventType for class org.apache.hadoop.yarn.server.resourcemanager.ahs.RMApplicationHistoryWriter$ForwardingEventHandler
2015-04-10 19:28:39,994 INFO org.apache.hadoop.yarn.event.AsyncDispatcher: Registering class org.apache.hadoop.yarn.server.resourcemanager.ahs.WritingHistoryEventType for class org.apache.hadoop.yarn.server.resourcemanager.ahs.RMApplicationHistoryWriter$ForwardingEventHandler
2015-04-10 19:28:39,994 INFO org.apache.hadoop.yarn.event.AsyncDispatcher: Registering class org.apache.hadoop.yarn.server.resourcemanager.ahs.WritingHistoryEventType for class org.apache.hadoop.yarn.server.resourcemanager.ahs.RMApplicationHistoryWriter$ForwardingEventHandler
2015-04-10 19:28:39,994 INFO org.apache.hadoop.yarn.event.AsyncDispatcher: Registering class org.apache.hadoop.yarn.server.resourcemanager.ahs.WritingHistoryEventType for class org.apache.hadoop.yarn.server.resourcemanager.ahs.RMApplicationHistoryWriter$ForwardingEventHandler
2015-04-10 19:28:39,995 INFO org.apache.hadoop.util.HostsFileReader: Refreshing hosts (include/exclude) list
2015-04-10 19:28:39,998 INFO org.apache.hadoop.conf.Configuration: found resource capacity-scheduler.xml at file:/gpfs/courses/cse587/spring2015/students/u2/hw4/Uploader/config-3674693/capacity-scheduler.xml
2015-04-10 19:28:40,051 INFO org.apache.hadoop.yarn.server.resourcemanager.scheduler.capacity.ParentQueue: root, capacity=1.0, asboluteCapacity=1.0, maxCapacity=1.0, asboluteMaxCapacity=1.0, state=RUNNING, acls=SUBMIT_APPLICATIONS:*ADMINISTER_QUEUE:*
2015-04-10 19:28:40,051 INFO org.apache.hadoop.yarn.server.resourcemanager.scheduler.capacity.ParentQueue: Initialized parent-queue root name=root, fullname=root
2015-04-10 19:28:40,060 INFO org.apache.hadoop.yarn.server.resourcemanager.scheduler.capacity.LeafQueue: Initializing default
capacity = 1.0 [= (float) configuredCapacity / 100 ]
asboluteCapacity = 1.0 [= parentAbsoluteCapacity * capacity ]
maxCapacity = 1.0 [= configuredMaxCapacity ]
absoluteMaxCapacity = 1.0 [= 1.0 maximumCapacity undefined, (parentAbsoluteMaxCapacity * maximumCapacity) / 100 otherwise ]
userLimit = 100 [= configuredUserLimit ]
userLimitFactor = 1.0 [= configuredUserLimitFactor ]
maxApplications = 10000 [= configuredMaximumSystemApplicationsPerQueue or (int)(configuredMaximumSystemApplications * absoluteCapacity)]
maxApplicationsPerUser = 10000 [= (int)(maxApplications * (userLimit / 100.0f) * userLimitFactor) ]
maxActiveApplications = 1 [= max((int)ceil((clusterResourceMemory / minimumAllocation) * maxAMResourcePerQueuePercent * absoluteMaxCapacity),1) ]
maxActiveAppsUsingAbsCap = 1 [= max((int)ceil((clusterResourceMemory / minimumAllocation) *maxAMResourcePercent * absoluteCapacity),1) ]
maxActiveApplicationsPerUser = 1 [= max((int)(maxActiveApplications * (userLimit / 100.0f) * userLimitFactor),1) ]
usedCapacity = 0.0 [= usedResourcesMemory / (clusterResourceMemory * absoluteCapacity)]
absoluteUsedCapacity = 0.0 [= usedResourcesMemory / clusterResourceMemory]
maxAMResourcePerQueuePercent = 0.1 [= configuredMaximumAMResourcePercent ]
minimumAllocationFactor = 0.875 [= (float)(maximumAllocationMemory - minimumAllocationMemory) / maximumAllocationMemory ]
numContainers = 0 [= currentNumContainers ]
state = RUNNING [= configuredState ]
acls = SUBMIT_APPLICATIONS:*ADMINISTER_QUEUE:* [= configuredAcls ]
nodeLocalityDelay = 40

2015-04-10 19:28:40,061 INFO org.apache.hadoop.yarn.server.resourcemanager.scheduler.capacity.CapacityScheduler: Initialized queue: default: capacity=1.0, absoluteCapacity=1.0, usedResources=<memory:0, vCores:0>, usedCapacity=0.0, absoluteUsedCapacity=0.0, numApps=0, numContainers=0
2015-04-10 19:28:40,061 INFO org.apache.hadoop.yarn.server.resourcemanager.scheduler.capacity.CapacityScheduler: Initialized queue: root: numChildQueue= 1, capacity=1.0, absoluteCapacity=1.0, usedResources=<memory:0, vCores:0>usedCapacity=0.0, numApps=0, numContainers=0
2015-04-10 19:28:40,061 INFO org.apache.hadoop.yarn.server.resourcemanager.scheduler.capacity.CapacityScheduler: Initialized root queue root: numChildQueue= 1, capacity=1.0, absoluteCapacity=1.0, usedResources=<memory:0, vCores:0>usedCapacity=0.0, numApps=0, numContainers=0
2015-04-10 19:28:40,061 INFO org.apache.hadoop.yarn.server.resourcemanager.scheduler.capacity.CapacityScheduler: Initialized CapacityScheduler with calculator=class org.apache.hadoop.yarn.util.resource.DefaultResourceCalculator, minimumAllocation=<<memory:1024, vCores:1>>, maximumAllocation=<<memory:8192, vCores:32>>, asynchronousScheduling=false, asyncScheduleInterval=5ms
2015-04-10 19:28:40,068 INFO org.apache.hadoop.yarn.server.resourcemanager.ResourceManager: Transitioning to active state
2015-04-10 19:28:40,074 INFO org.apache.hadoop.yarn.server.resourcemanager.security.RMContainerTokenSecretManager: Rolling master-key for container-tokens
2015-04-10 19:28:40,074 INFO org.apache.hadoop.yarn.server.resourcemanager.security.AMRMTokenSecretManager: Rolling master-key for amrm-tokens
2015-04-10 19:28:40,076 INFO org.apache.hadoop.yarn.server.resourcemanager.security.NMTokenSecretManagerInRM: Rolling master-key for nm-tokens
2015-04-10 19:28:40,077 INFO org.apache.hadoop.security.token.delegation.AbstractDelegationTokenSecretManager: Updating the current master key for generating delegation tokens
2015-04-10 19:28:40,077 INFO org.apache.hadoop.yarn.server.resourcemanager.security.RMDelegationTokenSecretManager: storing master key with keyID 1
2015-04-10 19:28:40,079 INFO org.apache.hadoop.security.token.delegation.AbstractDelegationTokenSecretManager: Starting expired delegation token remover thread, tokenRemoverScanInterval=60 min(s)
2015-04-10 19:28:40,079 INFO org.apache.hadoop.security.token.delegation.AbstractDelegationTokenSecretManager: Updating the current master key for generating delegation tokens
2015-04-10 19:28:40,079 INFO org.apache.hadoop.yarn.server.resourcemanager.security.RMDelegationTokenSecretManager: storing master key with keyID 2
2015-04-10 19:28:40,113 INFO org.apache.hadoop.ipc.CallQueueManager: Using callQueue class java.util.concurrent.LinkedBlockingQueue
2015-04-10 19:28:40,131 INFO org.apache.hadoop.ipc.Server: Starting Socket Reader #1 for port 8031
2015-04-10 19:28:40,151 INFO org.apache.hadoop.yarn.factories.impl.pb.RpcServerFactoryPBImpl: Adding protocol org.apache.hadoop.yarn.server.api.ResourceTrackerPB to the server
2015-04-10 19:28:40,152 INFO org.apache.hadoop.ipc.Server: IPC Server listener on 8031: starting
2015-04-10 19:28:40,152 INFO org.apache.hadoop.ipc.Server: IPC Server Responder: starting
2015-04-10 19:28:40,193 INFO org.apache.hadoop.ipc.CallQueueManager: Using callQueue class java.util.concurrent.LinkedBlockingQueue
2015-04-10 19:28:40,199 INFO org.apache.hadoop.ipc.Server: Starting Socket Reader #1 for port 8030
2015-04-10 19:28:40,209 INFO org.apache.hadoop.yarn.factories.impl.pb.RpcServerFactoryPBImpl: Adding protocol org.apache.hadoop.yarn.api.ApplicationMasterProtocolPB to the server
2015-04-10 19:28:40,210 INFO org.apache.hadoop.ipc.Server: IPC Server Responder: starting
2015-04-10 19:28:40,210 INFO org.apache.hadoop.ipc.Server: IPC Server listener on 8030: starting
2015-04-10 19:28:40,259 INFO org.apache.hadoop.ipc.CallQueueManager: Using callQueue class java.util.concurrent.LinkedBlockingQueue
2015-04-10 19:28:40,260 INFO org.apache.hadoop.ipc.Server: Starting Socket Reader #1 for port 8032
2015-04-10 19:28:40,264 INFO org.apache.hadoop.yarn.factories.impl.pb.RpcServerFactoryPBImpl: Adding protocol org.apache.hadoop.yarn.api.ApplicationClientProtocolPB to the server
2015-04-10 19:28:40,264 INFO org.apache.hadoop.ipc.Server: IPC Server Responder: starting
2015-04-10 19:28:40,264 INFO org.apache.hadoop.ipc.Server: IPC Server listener on 8032: starting
2015-04-10 19:28:40,273 INFO org.apache.hadoop.yarn.server.resourcemanager.ResourceManager: Transitioned to active state
2015-04-10 19:28:40,344 INFO org.mortbay.log: Logging to org.slf4j.impl.Log4jLoggerAdapter(org.mortbay.log) via org.mortbay.log.Slf4jLog
2015-04-10 19:28:40,348 INFO org.apache.hadoop.http.HttpRequestLog: Http request log for http.requests.resourcemanager is not defined
2015-04-10 19:28:40,359 INFO org.apache.hadoop.http.HttpServer2: Added global filter 'safety' (class=org.apache.hadoop.http.HttpServer2$QuotingInputFilter)
2015-04-10 19:28:40,367 INFO org.apache.hadoop.http.HttpServer2: Added filter YARNAuthenticationFilter (class=org.apache.hadoop.yarn.server.security.http.RMAuthenticationFilter) to context cluster
2015-04-10 19:28:40,367 INFO org.apache.hadoop.http.HttpServer2: Added filter YARNAuthenticationFilter (class=org.apache.hadoop.yarn.server.security.http.RMAuthenticationFilter) to context static
2015-04-10 19:28:40,367 INFO org.apache.hadoop.http.HttpServer2: Added filter YARNAuthenticationFilter (class=org.apache.hadoop.yarn.server.security.http.RMAuthenticationFilter) to context logs
2015-04-10 19:28:40,367 INFO org.apache.hadoop.http.HttpServer2: Added filter static_user_filter (class=org.apache.hadoop.http.lib.StaticUserWebFilter$StaticUserFilter) to context cluster
2015-04-10 19:28:40,367 INFO org.apache.hadoop.http.HttpServer2: Added filter static_user_filter (class=org.apache.hadoop.http.lib.StaticUserWebFilter$StaticUserFilter) to context static
2015-04-10 19:28:40,368 INFO org.apache.hadoop.http.HttpServer2: Added filter static_user_filter (class=org.apache.hadoop.http.lib.StaticUserWebFilter$StaticUserFilter) to context logs
2015-04-10 19:28:40,371 INFO org.apache.hadoop.http.HttpServer2: adding path spec: /cluster/*
2015-04-10 19:28:40,371 INFO org.apache.hadoop.http.HttpServer2: adding path spec: /ws/*
2015-04-10 19:28:40,382 INFO org.apache.hadoop.http.HttpServer2: Jetty bound to port 8088
2015-04-10 19:28:40,383 INFO org.mortbay.log: jetty-6.1.26
2015-04-10 19:28:40,409 WARN org.mortbay.log: Can't reuse /tmp/Jetty_k08n41s01_8088_cluster____.5k5gag, using /tmp/Jetty_k08n41s01_8088_cluster____.5k5gag_6092888492306712981
2015-04-10 19:28:40,409 INFO org.mortbay.log: Extract jar:file:/gpfs/util/academic/hadoop/2.5.1/hadoop-2.5.1/share/hadoop/yarn/hadoop-yarn-common-2.5.1.jar!/webapps/cluster to /tmp/Jetty_k08n41s01_8088_cluster____.5k5gag_6092888492306712981/webapp
2015-04-10 19:28:40,593 WARN org.apache.hadoop.security.authentication.server.AuthenticationFilter: 'signature.secret' configuration not set, using a random value as secret
2015-04-10 19:28:40,622 WARN org.apache.hadoop.security.authentication.server.AuthenticationFilter: 'signature.secret' configuration not set, using a random value as secret
2015-04-10 19:28:40,622 WARN org.apache.hadoop.security.authentication.server.AuthenticationFilter: 'signature.secret' configuration not set, using a random value as secret
2015-04-10 19:28:40,627 INFO org.mortbay.log: Started HttpServer2$SelectChannelConnectorWithSafeStartup@k08n41s01:8088
2015-04-10 19:28:40,627 INFO org.apache.hadoop.yarn.webapp.WebApps: Web app /cluster started at 8088
2015-04-10 19:28:40,986 INFO org.apache.hadoop.yarn.webapp.WebApps: Registered webapp guice modules
2015-04-10 19:28:41,008 INFO org.apache.hadoop.ipc.CallQueueManager: Using callQueue class java.util.concurrent.LinkedBlockingQueue
2015-04-10 19:28:41,009 INFO org.apache.hadoop.ipc.Server: Starting Socket Reader #1 for port 8033
2015-04-10 19:28:41,012 INFO org.apache.hadoop.yarn.factories.impl.pb.RpcServerFactoryPBImpl: Adding protocol org.apache.hadoop.yarn.server.api.ResourceManagerAdministrationProtocolPB to the server
2015-04-10 19:28:41,012 INFO org.apache.hadoop.ipc.Server: IPC Server Responder: starting
2015-04-10 19:28:41,012 INFO org.apache.hadoop.ipc.Server: IPC Server listener on 8033: starting
2015-04-10 19:28:42,688 INFO org.apache.hadoop.yarn.util.RackResolver: Resolved k08n41s02.ccr.buffalo.edu to /default-rack
2015-04-10 19:28:42,688 INFO org.apache.hadoop.yarn.util.RackResolver: Resolved k08n41s01.ccr.buffalo.edu to /default-rack
2015-04-10 19:28:42,697 INFO org.apache.hadoop.yarn.server.resourcemanager.ResourceTrackerService: NodeManager from node k08n41s02.ccr.buffalo.edu(cmPort: 45431 httpPort: 8042) registered with capability: <memory:8192, vCores:8>, assigned nodeId k08n41s02.ccr.buffalo.edu:45431
2015-04-10 19:28:42,697 INFO org.apache.hadoop.yarn.server.resourcemanager.ResourceTrackerService: NodeManager from node k08n41s01.ccr.buffalo.edu(cmPort: 60578 httpPort: 8042) registered with capability: <memory:8192, vCores:8>, assigned nodeId k08n41s01.ccr.buffalo.edu:60578
2015-04-10 19:28:42,697 INFO org.apache.hadoop.yarn.server.resourcemanager.rmnode.RMNodeImpl: k08n41s02.ccr.buffalo.edu:45431 Node Transitioned from NEW to RUNNING
2015-04-10 19:28:42,698 INFO org.apache.hadoop.yarn.server.resourcemanager.rmnode.RMNodeImpl: k08n41s01.ccr.buffalo.edu:60578 Node Transitioned from NEW to RUNNING
2015-04-10 19:28:42,701 INFO org.apache.hadoop.yarn.server.resourcemanager.scheduler.capacity.CapacityScheduler: Added node k08n41s02.ccr.buffalo.edu:45431 clusterResource: <memory:8192, vCores:8>
2015-04-10 19:28:42,702 INFO org.apache.hadoop.yarn.server.resourcemanager.scheduler.capacity.CapacityScheduler: Added node k08n41s01.ccr.buffalo.edu:60578 clusterResource: <memory:16384, vCores:16>
2015-04-10 19:28:58,634 INFO org.apache.hadoop.yarn.server.resourcemanager.ClientRMService: Allocated new applicationId: 1
2015-04-10 19:29:00,478 INFO org.apache.hadoop.yarn.server.resourcemanager.ClientRMService: Application with id 1 submitted by user u2
2015-04-10 19:29:00,480 INFO org.apache.hadoop.yarn.server.resourcemanager.rmapp.RMAppImpl: Storing application with id application_1428708520072_0001
2015-04-10 19:29:00,480 INFO org.apache.hadoop.yarn.server.resourcemanager.RMAuditLogger: USER=u2	IP=10.111.8.41	OPERATION=Submit Application Request	TARGET=ClientRMService	RESULT=SUCCESS	APPID=application_1428708520072_0001
2015-04-10 19:29:00,481 INFO org.apache.hadoop.yarn.server.resourcemanager.rmapp.RMAppImpl: application_1428708520072_0001 State change from NEW to NEW_SAVING
2015-04-10 19:29:00,492 INFO org.apache.hadoop.yarn.server.resourcemanager.recovery.RMStateStore: Storing info for app: application_1428708520072_0001
2015-04-10 19:29:00,493 INFO org.apache.hadoop.yarn.server.resourcemanager.rmapp.RMAppImpl: application_1428708520072_0001 State change from NEW_SAVING to SUBMITTED
2015-04-10 19:29:00,494 INFO org.apache.hadoop.yarn.server.resourcemanager.scheduler.capacity.ParentQueue: Application added - appId: application_1428708520072_0001 user: u2 leaf-queue of parent: root #applications: 1
2015-04-10 19:29:00,494 INFO org.apache.hadoop.yarn.server.resourcemanager.scheduler.capacity.CapacityScheduler: Accepted application application_1428708520072_0001 from user: u2, in queue: default
2015-04-10 19:29:00,502 INFO org.apache.hadoop.yarn.server.resourcemanager.rmapp.RMAppImpl: application_1428708520072_0001 State change from SUBMITTED to ACCEPTED
2015-04-10 19:29:00,503 INFO org.apache.hadoop.yarn.server.resourcemanager.ApplicationMasterService: Registering app attempt : appattempt_1428708520072_0001_000001
2015-04-10 19:29:00,511 INFO org.apache.hadoop.yarn.server.resourcemanager.rmapp.attempt.RMAppAttemptImpl: appattempt_1428708520072_0001_000001 State change from NEW to SUBMITTED
2015-04-10 19:29:00,530 INFO org.apache.hadoop.yarn.server.resourcemanager.scheduler.capacity.LeafQueue: Application application_1428708520072_0001 from user: u2 activated in queue: default
2015-04-10 19:29:00,530 INFO org.apache.hadoop.yarn.server.resourcemanager.scheduler.capacity.LeafQueue: Application added - appId: application_1428708520072_0001 user: org.apache.hadoop.yarn.server.resourcemanager.scheduler.capacity.LeafQueue$User@1e883644, leaf-queue: default #user-pending-applications: 0 #user-active-applications: 1 #queue-pending-applications: 0 #queue-active-applications: 1
2015-04-10 19:29:00,530 INFO org.apache.hadoop.yarn.server.resourcemanager.scheduler.capacity.CapacityScheduler: Added Application Attempt appattempt_1428708520072_0001_000001 to scheduler from user u2 in queue default
2015-04-10 19:29:00,531 INFO org.apache.hadoop.yarn.server.resourcemanager.rmapp.attempt.RMAppAttemptImpl: appattempt_1428708520072_0001_000001 State change from SUBMITTED to SCHEDULED
2015-04-10 19:29:00,817 INFO org.apache.hadoop.yarn.server.resourcemanager.rmcontainer.RMContainerImpl: container_1428708520072_0001_01_000001 Container Transitioned from NEW to ALLOCATED
2015-04-10 19:29:00,817 INFO org.apache.hadoop.yarn.server.resourcemanager.RMAuditLogger: USER=u2	OPERATION=AM Allocated Container	TARGET=SchedulerApp	RESULT=SUCCESS	APPID=application_1428708520072_0001	CONTAINERID=container_1428708520072_0001_01_000001
2015-04-10 19:29:00,818 INFO org.apache.hadoop.yarn.server.resourcemanager.scheduler.SchedulerNode: Assigned container container_1428708520072_0001_01_000001 of capacity <memory:2048, vCores:1> on host k08n41s01.ccr.buffalo.edu:60578, which has 1 containers, <memory:2048, vCores:1> used and <memory:6144, vCores:7> available after allocation
2015-04-10 19:29:00,818 INFO org.apache.hadoop.yarn.server.resourcemanager.scheduler.capacity.LeafQueue: assignedContainer application attempt=appattempt_1428708520072_0001_000001 container=Container: [ContainerId: container_1428708520072_0001_01_000001, NodeId: k08n41s01.ccr.buffalo.edu:60578, NodeHttpAddress: k08n41s01.ccr.buffalo.edu:8042, Resource: <memory:2048, vCores:1>, Priority: 0, Token: null, ] queue=default: capacity=1.0, absoluteCapacity=1.0, usedResources=<memory:0, vCores:0>, usedCapacity=0.0, absoluteUsedCapacity=0.0, numApps=1, numContainers=0 clusterResource=<memory:16384, vCores:16>
2015-04-10 19:29:00,818 INFO org.apache.hadoop.yarn.server.resourcemanager.scheduler.capacity.ParentQueue: Re-sorting assigned queue: root.default stats: default: capacity=1.0, absoluteCapacity=1.0, usedResources=<memory:2048, vCores:1>, usedCapacity=0.125, absoluteUsedCapacity=0.125, numApps=1, numContainers=1
2015-04-10 19:29:00,818 INFO org.apache.hadoop.yarn.server.resourcemanager.scheduler.capacity.ParentQueue: assignedContainer queue=root usedCapacity=0.125 absoluteUsedCapacity=0.125 used=<memory:2048, vCores:1> cluster=<memory:16384, vCores:16>
2015-04-10 19:29:00,820 INFO org.apache.hadoop.yarn.server.resourcemanager.security.NMTokenSecretManagerInRM: Sending NMToken for nodeId : k08n41s01.ccr.buffalo.edu:60578 for container : container_1428708520072_0001_01_000001
2015-04-10 19:29:00,825 INFO org.apache.hadoop.yarn.server.resourcemanager.rmcontainer.RMContainerImpl: container_1428708520072_0001_01_000001 Container Transitioned from ALLOCATED to ACQUIRED
2015-04-10 19:29:00,825 INFO org.apache.hadoop.yarn.server.resourcemanager.security.NMTokenSecretManagerInRM: Clear node set for appattempt_1428708520072_0001_000001
2015-04-10 19:29:00,828 INFO org.apache.hadoop.yarn.server.resourcemanager.rmapp.attempt.RMAppAttemptImpl: Storing attempt: AppId: application_1428708520072_0001 AttemptId: appattempt_1428708520072_0001_000001 MasterContainer: Container: [ContainerId: container_1428708520072_0001_01_000001, NodeId: k08n41s01.ccr.buffalo.edu:60578, NodeHttpAddress: k08n41s01.ccr.buffalo.edu:8042, Resource: <memory:2048, vCores:1>, Priority: 0, Token: Token { kind: ContainerToken, service: 10.111.8.41:60578 }, ]
2015-04-10 19:29:00,831 INFO org.apache.hadoop.yarn.server.resourcemanager.rmapp.attempt.RMAppAttemptImpl: appattempt_1428708520072_0001_000001 State change from SCHEDULED to ALLOCATED_SAVING
2015-04-10 19:29:00,841 INFO org.apache.hadoop.yarn.server.resourcemanager.rmapp.attempt.RMAppAttemptImpl: appattempt_1428708520072_0001_000001 State change from ALLOCATED_SAVING to ALLOCATED
2015-04-10 19:29:00,844 INFO org.apache.hadoop.yarn.server.resourcemanager.amlauncher.AMLauncher: Launching masterappattempt_1428708520072_0001_000001
2015-04-10 19:29:00,877 INFO org.apache.hadoop.yarn.server.resourcemanager.amlauncher.AMLauncher: Setting up container Container: [ContainerId: container_1428708520072_0001_01_000001, NodeId: k08n41s01.ccr.buffalo.edu:60578, NodeHttpAddress: k08n41s01.ccr.buffalo.edu:8042, Resource: <memory:2048, vCores:1>, Priority: 0, Token: Token { kind: ContainerToken, service: 10.111.8.41:60578 }, ] for AM appattempt_1428708520072_0001_000001
2015-04-10 19:29:00,877 INFO org.apache.hadoop.yarn.server.resourcemanager.amlauncher.AMLauncher: Command to launch container container_1428708520072_0001_01_000001 : $JAVA_HOME/bin/java -Dlog4j.configuration=container-log4j.properties -Dyarn.app.container.log.dir=<LOG_DIR> -Dyarn.app.container.log.filesize=0 -Dhadoop.root.logger=INFO,CLA  -Xmx1024m org.apache.hadoop.mapreduce.v2.app.MRAppMaster 1><LOG_DIR>/stdout 2><LOG_DIR>/stderr 
2015-04-10 19:29:01,154 INFO org.apache.hadoop.yarn.server.resourcemanager.amlauncher.AMLauncher: Done launching container Container: [ContainerId: container_1428708520072_0001_01_000001, NodeId: k08n41s01.ccr.buffalo.edu:60578, NodeHttpAddress: k08n41s01.ccr.buffalo.edu:8042, Resource: <memory:2048, vCores:1>, Priority: 0, Token: Token { kind: ContainerToken, service: 10.111.8.41:60578 }, ] for AM appattempt_1428708520072_0001_000001
2015-04-10 19:29:01,154 INFO org.apache.hadoop.yarn.server.resourcemanager.rmapp.attempt.RMAppAttemptImpl: appattempt_1428708520072_0001_000001 State change from ALLOCATED to LAUNCHED
2015-04-10 19:29:01,813 INFO org.apache.hadoop.yarn.server.resourcemanager.rmcontainer.RMContainerImpl: container_1428708520072_0001_01_000001 Container Transitioned from ACQUIRED to RUNNING
2015-04-10 19:29:07,509 INFO SecurityLogger.org.apache.hadoop.ipc.Server: Auth successful for appattempt_1428708520072_0001_000001 (auth:SIMPLE)
2015-04-10 19:29:07,516 INFO org.apache.hadoop.yarn.server.resourcemanager.ApplicationMasterService: AM registration appattempt_1428708520072_0001_000001
2015-04-10 19:29:07,517 INFO org.apache.hadoop.yarn.server.resourcemanager.RMAuditLogger: USER=u2	IP=10.111.8.41	OPERATION=Register App Master	TARGET=ApplicationMasterService	RESULT=SUCCESS	APPID=application_1428708520072_0001	APPATTEMPTID=appattempt_1428708520072_0001_000001
2015-04-10 19:29:07,518 INFO org.apache.hadoop.yarn.server.resourcemanager.rmapp.attempt.RMAppAttemptImpl: appattempt_1428708520072_0001_000001 State change from LAUNCHED to RUNNING
2015-04-10 19:29:07,518 INFO org.apache.hadoop.yarn.server.resourcemanager.rmapp.RMAppImpl: application_1428708520072_0001 State change from ACCEPTED to RUNNING
2015-04-10 19:29:08,813 INFO org.apache.hadoop.yarn.server.resourcemanager.rmcontainer.RMContainerImpl: container_1428708520072_0001_01_000002 Container Transitioned from NEW to ALLOCATED
2015-04-10 19:29:08,813 INFO org.apache.hadoop.yarn.server.resourcemanager.RMAuditLogger: USER=u2	OPERATION=AM Allocated Container	TARGET=SchedulerApp	RESULT=SUCCESS	APPID=application_1428708520072_0001	CONTAINERID=container_1428708520072_0001_01_000002
2015-04-10 19:29:08,813 INFO org.apache.hadoop.yarn.server.resourcemanager.scheduler.SchedulerNode: Assigned container container_1428708520072_0001_01_000002 of capacity <memory:1024, vCores:1> on host k08n41s02.ccr.buffalo.edu:45431, which has 1 containers, <memory:1024, vCores:1> used and <memory:7168, vCores:7> available after allocation
2015-04-10 19:29:08,814 INFO org.apache.hadoop.yarn.server.resourcemanager.scheduler.capacity.LeafQueue: assignedContainer application attempt=appattempt_1428708520072_0001_000001 container=Container: [ContainerId: container_1428708520072_0001_01_000002, NodeId: k08n41s02.ccr.buffalo.edu:45431, NodeHttpAddress: k08n41s02.ccr.buffalo.edu:8042, Resource: <memory:1024, vCores:1>, Priority: 20, Token: null, ] queue=default: capacity=1.0, absoluteCapacity=1.0, usedResources=<memory:2048, vCores:1>, usedCapacity=0.125, absoluteUsedCapacity=0.125, numApps=1, numContainers=1 clusterResource=<memory:16384, vCores:16>
2015-04-10 19:29:08,814 INFO org.apache.hadoop.yarn.server.resourcemanager.scheduler.capacity.ParentQueue: Re-sorting assigned queue: root.default stats: default: capacity=1.0, absoluteCapacity=1.0, usedResources=<memory:3072, vCores:2>, usedCapacity=0.1875, absoluteUsedCapacity=0.1875, numApps=1, numContainers=2
2015-04-10 19:29:08,814 INFO org.apache.hadoop.yarn.server.resourcemanager.scheduler.capacity.ParentQueue: assignedContainer queue=root usedCapacity=0.1875 absoluteUsedCapacity=0.1875 used=<memory:3072, vCores:2> cluster=<memory:16384, vCores:16>
2015-04-10 19:29:08,814 INFO org.apache.hadoop.yarn.server.resourcemanager.rmcontainer.RMContainerImpl: container_1428708520072_0001_01_000003 Container Transitioned from NEW to ALLOCATED
2015-04-10 19:29:08,814 INFO org.apache.hadoop.yarn.server.resourcemanager.RMAuditLogger: USER=u2	OPERATION=AM Allocated Container	TARGET=SchedulerApp	RESULT=SUCCESS	APPID=application_1428708520072_0001	CONTAINERID=container_1428708520072_0001_01_000003
2015-04-10 19:29:08,814 INFO org.apache.hadoop.yarn.server.resourcemanager.scheduler.SchedulerNode: Assigned container container_1428708520072_0001_01_000003 of capacity <memory:1024, vCores:1> on host k08n41s02.ccr.buffalo.edu:45431, which has 2 containers, <memory:2048, vCores:2> used and <memory:6144, vCores:6> available after allocation
2015-04-10 19:29:08,814 INFO org.apache.hadoop.yarn.server.resourcemanager.scheduler.capacity.LeafQueue: assignedContainer application attempt=appattempt_1428708520072_0001_000001 container=Container: [ContainerId: container_1428708520072_0001_01_000003, NodeId: k08n41s02.ccr.buffalo.edu:45431, NodeHttpAddress: k08n41s02.ccr.buffalo.edu:8042, Resource: <memory:1024, vCores:1>, Priority: 20, Token: null, ] queue=default: capacity=1.0, absoluteCapacity=1.0, usedResources=<memory:3072, vCores:2>, usedCapacity=0.1875, absoluteUsedCapacity=0.1875, numApps=1, numContainers=2 clusterResource=<memory:16384, vCores:16>
2015-04-10 19:29:08,814 INFO org.apache.hadoop.yarn.server.resourcemanager.scheduler.capacity.ParentQueue: Re-sorting assigned queue: root.default stats: default: capacity=1.0, absoluteCapacity=1.0, usedResources=<memory:4096, vCores:3>, usedCapacity=0.25, absoluteUsedCapacity=0.25, numApps=1, numContainers=3
2015-04-10 19:29:08,815 INFO org.apache.hadoop.yarn.server.resourcemanager.scheduler.capacity.ParentQueue: assignedContainer queue=root usedCapacity=0.25 absoluteUsedCapacity=0.25 used=<memory:4096, vCores:3> cluster=<memory:16384, vCores:16>
2015-04-10 19:29:09,586 INFO org.apache.hadoop.yarn.server.resourcemanager.security.NMTokenSecretManagerInRM: Sending NMToken for nodeId : k08n41s02.ccr.buffalo.edu:45431 for container : container_1428708520072_0001_01_000002
2015-04-10 19:29:09,587 INFO org.apache.hadoop.yarn.server.resourcemanager.rmcontainer.RMContainerImpl: container_1428708520072_0001_01_000002 Container Transitioned from ALLOCATED to ACQUIRED
2015-04-10 19:29:09,588 INFO org.apache.hadoop.yarn.server.resourcemanager.rmcontainer.RMContainerImpl: container_1428708520072_0001_01_000003 Container Transitioned from ALLOCATED to ACQUIRED
2015-04-10 19:29:10,605 INFO org.apache.hadoop.yarn.server.resourcemanager.scheduler.AppSchedulingInfo: checking for deactivate... 
2015-04-10 19:29:10,830 INFO org.apache.hadoop.yarn.server.resourcemanager.rmcontainer.RMContainerImpl: container_1428708520072_0001_01_000002 Container Transitioned from ACQUIRED to RUNNING
2015-04-10 19:29:10,831 INFO org.apache.hadoop.yarn.server.resourcemanager.rmcontainer.RMContainerImpl: container_1428708520072_0001_01_000003 Container Transitioned from ACQUIRED to RUNNING
2015-04-10 19:29:16,916 INFO org.apache.hadoop.yarn.server.resourcemanager.rmapp.attempt.RMAppAttemptImpl: Updating application attempt appattempt_1428708520072_0001_000001 with final state: FINISHING, and exit status: -1000
2015-04-10 19:29:16,917 INFO org.apache.hadoop.yarn.server.resourcemanager.rmapp.attempt.RMAppAttemptImpl: appattempt_1428708520072_0001_000001 State change from RUNNING to FINAL_SAVING
2015-04-10 19:29:16,917 INFO org.apache.hadoop.yarn.server.resourcemanager.rmapp.RMAppImpl: Updating application application_1428708520072_0001 with final state: FINISHING
2015-04-10 19:29:16,918 INFO org.apache.hadoop.yarn.server.resourcemanager.rmapp.RMAppImpl: application_1428708520072_0001 State change from RUNNING to FINAL_SAVING
2015-04-10 19:29:16,919 INFO org.apache.hadoop.yarn.server.resourcemanager.recovery.RMStateStore: Updating info for app: application_1428708520072_0001
2015-04-10 19:29:16,920 INFO org.apache.hadoop.yarn.server.resourcemanager.rmapp.attempt.RMAppAttemptImpl: appattempt_1428708520072_0001_000001 State change from FINAL_SAVING to FINISHING
2015-04-10 19:29:16,921 INFO org.apache.hadoop.yarn.server.resourcemanager.rmapp.RMAppImpl: application_1428708520072_0001 State change from FINAL_SAVING to FINISHING
2015-04-10 19:29:17,624 INFO org.apache.hadoop.yarn.server.resourcemanager.rmcontainer.RMContainerImpl: container_1428708520072_0001_01_000002 Container Transitioned from RUNNING to COMPLETED
2015-04-10 19:29:17,624 INFO org.apache.hadoop.yarn.server.resourcemanager.scheduler.common.fica.FiCaSchedulerApp: Completed container: container_1428708520072_0001_01_000002 in state: COMPLETED event:FINISHED
2015-04-10 19:29:17,624 INFO org.apache.hadoop.yarn.server.resourcemanager.RMAuditLogger: USER=u2	OPERATION=AM Released Container	TARGET=SchedulerApp	RESULT=SUCCESS	APPID=application_1428708520072_0001	CONTAINERID=container_1428708520072_0001_01_000002
2015-04-10 19:29:17,624 INFO org.apache.hadoop.yarn.server.resourcemanager.scheduler.SchedulerNode: Released container container_1428708520072_0001_01_000002 of capacity <memory:1024, vCores:1> on host k08n41s02.ccr.buffalo.edu:45431, which currently has 1 containers, <memory:1024, vCores:1> used and <memory:7168, vCores:7> available, release resources=true
2015-04-10 19:29:17,624 INFO org.apache.hadoop.yarn.server.resourcemanager.scheduler.capacity.LeafQueue: default used=<memory:3072, vCores:2> numContainers=2 user=u2 user-resources=<memory:3072, vCores:2>
2015-04-10 19:29:17,625 INFO org.apache.hadoop.yarn.server.resourcemanager.scheduler.capacity.LeafQueue: completedContainer container=Container: [ContainerId: container_1428708520072_0001_01_000002, NodeId: k08n41s02.ccr.buffalo.edu:45431, NodeHttpAddress: k08n41s02.ccr.buffalo.edu:8042, Resource: <memory:1024, vCores:1>, Priority: 20, Token: Token { kind: ContainerToken, service: 10.111.8.141:45431 }, ] queue=default: capacity=1.0, absoluteCapacity=1.0, usedResources=<memory:3072, vCores:2>, usedCapacity=0.1875, absoluteUsedCapacity=0.1875, numApps=1, numContainers=2 cluster=<memory:16384, vCores:16>
2015-04-10 19:29:17,625 INFO org.apache.hadoop.yarn.server.resourcemanager.scheduler.capacity.ParentQueue: completedContainer queue=root usedCapacity=0.1875 absoluteUsedCapacity=0.1875 used=<memory:3072, vCores:2> cluster=<memory:16384, vCores:16>
2015-04-10 19:29:17,625 INFO org.apache.hadoop.yarn.server.resourcemanager.scheduler.capacity.ParentQueue: Re-sorting completed queue: root.default stats: default: capacity=1.0, absoluteCapacity=1.0, usedResources=<memory:3072, vCores:2>, usedCapacity=0.1875, absoluteUsedCapacity=0.1875, numApps=1, numContainers=2
2015-04-10 19:29:17,625 INFO org.apache.hadoop.yarn.server.resourcemanager.scheduler.capacity.CapacityScheduler: Application attempt appattempt_1428708520072_0001_000001 released container container_1428708520072_0001_01_000002 on node: host: k08n41s02.ccr.buffalo.edu:45431 #containers=1 available=7168 used=1024 with event: FINISHED
2015-04-10 19:29:17,625 INFO org.apache.hadoop.yarn.server.resourcemanager.rmcontainer.RMContainerImpl: container_1428708520072_0001_01_000003 Container Transitioned from RUNNING to COMPLETED
2015-04-10 19:29:17,625 INFO org.apache.hadoop.yarn.server.resourcemanager.scheduler.common.fica.FiCaSchedulerApp: Completed container: container_1428708520072_0001_01_000003 in state: COMPLETED event:FINISHED
2015-04-10 19:29:17,626 INFO org.apache.hadoop.yarn.server.resourcemanager.RMAuditLogger: USER=u2	OPERATION=AM Released Container	TARGET=SchedulerApp	RESULT=SUCCESS	APPID=application_1428708520072_0001	CONTAINERID=container_1428708520072_0001_01_000003
2015-04-10 19:29:17,626 INFO org.apache.hadoop.yarn.server.resourcemanager.scheduler.SchedulerNode: Released container container_1428708520072_0001_01_000003 of capacity <memory:1024, vCores:1> on host k08n41s02.ccr.buffalo.edu:45431, which currently has 0 containers, <memory:0, vCores:0> used and <memory:8192, vCores:8> available, release resources=true
2015-04-10 19:29:17,626 INFO org.apache.hadoop.yarn.server.resourcemanager.scheduler.capacity.LeafQueue: default used=<memory:2048, vCores:1> numContainers=1 user=u2 user-resources=<memory:2048, vCores:1>
2015-04-10 19:29:17,626 INFO org.apache.hadoop.yarn.server.resourcemanager.scheduler.capacity.LeafQueue: completedContainer container=Container: [ContainerId: container_1428708520072_0001_01_000003, NodeId: k08n41s02.ccr.buffalo.edu:45431, NodeHttpAddress: k08n41s02.ccr.buffalo.edu:8042, Resource: <memory:1024, vCores:1>, Priority: 20, Token: Token { kind: ContainerToken, service: 10.111.8.141:45431 }, ] queue=default: capacity=1.0, absoluteCapacity=1.0, usedResources=<memory:2048, vCores:1>, usedCapacity=0.125, absoluteUsedCapacity=0.125, numApps=1, numContainers=1 cluster=<memory:16384, vCores:16>
2015-04-10 19:29:17,626 INFO org.apache.hadoop.yarn.server.resourcemanager.scheduler.capacity.ParentQueue: completedContainer queue=root usedCapacity=0.125 absoluteUsedCapacity=0.125 used=<memory:2048, vCores:1> cluster=<memory:16384, vCores:16>
2015-04-10 19:29:17,626 INFO org.apache.hadoop.yarn.server.resourcemanager.scheduler.capacity.ParentQueue: Re-sorting completed queue: root.default stats: default: capacity=1.0, absoluteCapacity=1.0, usedResources=<memory:2048, vCores:1>, usedCapacity=0.125, absoluteUsedCapacity=0.125, numApps=1, numContainers=1
2015-04-10 19:29:17,627 INFO org.apache.hadoop.yarn.server.resourcemanager.scheduler.capacity.CapacityScheduler: Application attempt appattempt_1428708520072_0001_000001 released container container_1428708520072_0001_01_000003 on node: host: k08n41s02.ccr.buffalo.edu:45431 #containers=0 available=8192 used=0 with event: FINISHED
2015-04-10 19:29:23,861 INFO org.apache.hadoop.yarn.server.resourcemanager.rmcontainer.RMContainerImpl: container_1428708520072_0001_01_000001 Container Transitioned from RUNNING to COMPLETED
2015-04-10 19:29:23,861 INFO org.apache.hadoop.yarn.server.resourcemanager.scheduler.common.fica.FiCaSchedulerApp: Completed container: container_1428708520072_0001_01_000001 in state: COMPLETED event:FINISHED
2015-04-10 19:29:23,861 INFO org.apache.hadoop.yarn.server.resourcemanager.ApplicationMasterService: Unregistering app attempt : appattempt_1428708520072_0001_000001
2015-04-10 19:29:23,861 INFO org.apache.hadoop.yarn.server.resourcemanager.RMAuditLogger: USER=u2	OPERATION=AM Released Container	TARGET=SchedulerApp	RESULT=SUCCESS	APPID=application_1428708520072_0001	CONTAINERID=container_1428708520072_0001_01_000001
2015-04-10 19:29:23,862 INFO org.apache.hadoop.yarn.server.resourcemanager.scheduler.SchedulerNode: Released container container_1428708520072_0001_01_000001 of capacity <memory:2048, vCores:1> on host k08n41s01.ccr.buffalo.edu:60578, which currently has 0 containers, <memory:0, vCores:0> used and <memory:8192, vCores:8> available, release resources=true
2015-04-10 19:29:23,862 INFO org.apache.hadoop.yarn.server.resourcemanager.scheduler.capacity.LeafQueue: default used=<memory:0, vCores:0> numContainers=0 user=u2 user-resources=<memory:0, vCores:0>
2015-04-10 19:29:23,862 INFO org.apache.hadoop.yarn.server.resourcemanager.scheduler.capacity.LeafQueue: completedContainer container=Container: [ContainerId: container_1428708520072_0001_01_000001, NodeId: k08n41s01.ccr.buffalo.edu:60578, NodeHttpAddress: k08n41s01.ccr.buffalo.edu:8042, Resource: <memory:2048, vCores:1>, Priority: 0, Token: Token { kind: ContainerToken, service: 10.111.8.41:60578 }, ] queue=default: capacity=1.0, absoluteCapacity=1.0, usedResources=<memory:0, vCores:0>, usedCapacity=0.0, absoluteUsedCapacity=0.0, numApps=1, numContainers=0 cluster=<memory:16384, vCores:16>
2015-04-10 19:29:23,862 INFO org.apache.hadoop.yarn.server.resourcemanager.scheduler.capacity.ParentQueue: completedContainer queue=root usedCapacity=0.0 absoluteUsedCapacity=0.0 used=<memory:0, vCores:0> cluster=<memory:16384, vCores:16>
2015-04-10 19:29:23,862 INFO org.apache.hadoop.yarn.server.resourcemanager.scheduler.capacity.ParentQueue: Re-sorting completed queue: root.default stats: default: capacity=1.0, absoluteCapacity=1.0, usedResources=<memory:0, vCores:0>, usedCapacity=0.0, absoluteUsedCapacity=0.0, numApps=1, numContainers=0
2015-04-10 19:29:23,862 INFO org.apache.hadoop.yarn.server.resourcemanager.scheduler.capacity.CapacityScheduler: Application attempt appattempt_1428708520072_0001_000001 released container container_1428708520072_0001_01_000001 on node: host: k08n41s01.ccr.buffalo.edu:60578 #containers=0 available=8192 used=0 with event: FINISHED
2015-04-10 19:29:23,863 INFO org.apache.hadoop.yarn.server.resourcemanager.rmapp.attempt.RMAppAttemptImpl: appattempt_1428708520072_0001_000001 State change from FINISHING to FINISHED
2015-04-10 19:29:23,865 INFO org.apache.hadoop.yarn.server.resourcemanager.rmapp.RMAppImpl: application_1428708520072_0001 State change from FINISHING to FINISHED
2015-04-10 19:29:23,865 INFO org.apache.hadoop.yarn.server.resourcemanager.scheduler.capacity.CapacityScheduler: Application Attempt appattempt_1428708520072_0001_000001 is done. finalState=FINISHED
2015-04-10 19:29:23,865 INFO org.apache.hadoop.yarn.server.resourcemanager.scheduler.AppSchedulingInfo: Application application_1428708520072_0001 requests cleared
2015-04-10 19:29:23,866 INFO org.apache.hadoop.yarn.server.resourcemanager.scheduler.capacity.LeafQueue: Application removed - appId: application_1428708520072_0001 user: u2 queue: default #user-pending-applications: 0 #user-active-applications: 0 #queue-pending-applications: 0 #queue-active-applications: 0
2015-04-10 19:29:23,866 INFO org.apache.hadoop.yarn.server.resourcemanager.amlauncher.AMLauncher: Cleaning master appattempt_1428708520072_0001_000001
2015-04-10 19:29:23,867 INFO org.apache.hadoop.yarn.server.resourcemanager.scheduler.capacity.ParentQueue: Application removed - appId: application_1428708520072_0001 user: u2 leaf-queue of parent: root #applications: 0
2015-04-10 19:29:23,867 INFO org.apache.hadoop.yarn.server.resourcemanager.RMAuditLogger: USER=u2	OPERATION=Application Finished - Succeeded	TARGET=RMAppManager	RESULT=SUCCESS	APPID=application_1428708520072_0001
2015-04-10 19:29:23,870 INFO org.apache.hadoop.yarn.server.resourcemanager.RMAppManager$ApplicationSummary: appId=application_1428708520072_0001,name=Uploader.jar,user=u2,queue=default,state=FINISHED,trackingUrl=http://k08n41s01:8088/proxy/application_1428708520072_0001/jobhistory/job/job_1428708520072_0001,appMasterHost=k08n41s01,startTime=1428708540478,finishTime=1428708556917,finalStatus=SUCCEEDED
2015-04-10 19:30:20,603 ERROR org.apache.hadoop.yarn.server.resourcemanager.ResourceManager: RECEIVED SIGNAL 15: SIGTERM
2015-04-10 19:30:20,608 INFO org.mortbay.log: Stopped HttpServer2$SelectChannelConnectorWithSafeStartup@k08n41s01:8088
2015-04-10 19:30:20,708 INFO org.apache.hadoop.ipc.Server: Stopping server on 8032
2015-04-10 19:30:20,709 INFO org.apache.hadoop.ipc.Server: Stopping IPC Server listener on 8032
2015-04-10 19:30:20,709 INFO org.apache.hadoop.ipc.Server: Stopping server on 8033
2015-04-10 19:30:20,709 INFO org.apache.hadoop.ipc.Server: Stopping IPC Server Responder
2015-04-10 19:30:20,709 INFO org.apache.hadoop.ipc.Server: Stopping IPC Server listener on 8033
2015-04-10 19:30:20,709 INFO org.apache.hadoop.ipc.Server: Stopping IPC Server Responder
2015-04-10 19:30:20,709 INFO org.apache.hadoop.yarn.server.resourcemanager.ResourceManager: Transitioning to standby state
2015-04-10 19:30:20,709 INFO org.apache.hadoop.metrics2.impl.MetricsSystemImpl: Stopping ResourceManager metrics system...
2015-04-10 19:30:20,710 INFO org.apache.hadoop.metrics2.impl.MetricsSystemImpl: ResourceManager metrics system stopped.
2015-04-10 19:30:20,710 INFO org.apache.hadoop.metrics2.impl.MetricsSystemImpl: ResourceManager metrics system shutdown complete.
2015-04-10 19:30:20,710 INFO org.apache.hadoop.yarn.event.AsyncDispatcher: AsyncDispatcher is draining to stop, igonring any new events.
2015-04-10 19:30:20,710 WARN org.apache.hadoop.yarn.server.resourcemanager.amlauncher.ApplicationMasterLauncher: org.apache.hadoop.yarn.server.resourcemanager.amlauncher.ApplicationMasterLauncher$LauncherThread interrupted. Returning.
2015-04-10 19:30:20,714 INFO org.apache.hadoop.ipc.Server: Stopping server on 8030
2015-04-10 19:30:20,720 INFO org.apache.hadoop.ipc.Server: Stopping IPC Server listener on 8030
2015-04-10 19:30:20,721 INFO org.apache.hadoop.ipc.Server: Stopping server on 8031
2015-04-10 19:30:20,721 INFO org.apache.hadoop.ipc.Server: Stopping IPC Server Responder
2015-04-10 19:30:20,721 INFO org.apache.hadoop.ipc.Server: Stopping IPC Server listener on 8031
2015-04-10 19:30:20,721 INFO org.apache.hadoop.ipc.Server: Stopping IPC Server Responder
2015-04-10 19:30:20,721 ERROR org.apache.hadoop.yarn.server.resourcemanager.ResourceManager: Returning, interrupted : java.lang.InterruptedException
2015-04-10 19:30:20,723 INFO org.apache.hadoop.yarn.util.AbstractLivelinessMonitor: NMLivelinessMonitor thread interrupted
2015-04-10 19:30:20,723 INFO org.apache.hadoop.yarn.event.AsyncDispatcher: AsyncDispatcher is draining to stop, igonring any new events.
2015-04-10 19:30:20,723 INFO org.apache.hadoop.yarn.event.AsyncDispatcher: AsyncDispatcher is draining to stop, igonring any new events.
2015-04-10 19:30:20,723 INFO org.apache.hadoop.yarn.event.AsyncDispatcher: AsyncDispatcher is draining to stop, igonring any new events.
2015-04-10 19:30:20,725 INFO org.apache.hadoop.yarn.event.AsyncDispatcher: AsyncDispatcher is draining to stop, igonring any new events.
2015-04-10 19:30:20,726 INFO org.apache.hadoop.yarn.event.AsyncDispatcher: AsyncDispatcher is draining to stop, igonring any new events.
2015-04-10 19:30:20,736 INFO org.apache.hadoop.yarn.event.AsyncDispatcher: AsyncDispatcher is draining to stop, igonring any new events.
2015-04-10 19:30:20,737 INFO org.apache.hadoop.yarn.event.AsyncDispatcher: AsyncDispatcher is draining to stop, igonring any new events.
2015-04-10 19:30:20,738 INFO org.apache.hadoop.yarn.event.AsyncDispatcher: AsyncDispatcher is draining to stop, igonring any new events.
2015-04-10 19:30:20,738 INFO org.apache.hadoop.yarn.event.AsyncDispatcher: AsyncDispatcher is draining to stop, igonring any new events.
2015-04-10 19:30:20,738 INFO org.apache.hadoop.yarn.event.AsyncDispatcher: AsyncDispatcher is draining to stop, igonring any new events.
2015-04-10 19:30:20,739 INFO org.apache.hadoop.yarn.util.AbstractLivelinessMonitor: AMLivelinessMonitor thread interrupted
2015-04-10 19:30:20,739 INFO org.apache.hadoop.yarn.util.AbstractLivelinessMonitor: AMLivelinessMonitor thread interrupted
2015-04-10 19:30:20,739 INFO org.apache.hadoop.yarn.util.AbstractLivelinessMonitor: org.apache.hadoop.yarn.server.resourcemanager.rmcontainer.ContainerAllocationExpirer thread interrupted
2015-04-10 19:30:20,739 ERROR org.apache.hadoop.security.token.delegation.AbstractDelegationTokenSecretManager: ExpiredTokenRemover received java.lang.InterruptedException: sleep interrupted
2015-04-10 19:30:20,739 INFO org.apache.hadoop.yarn.server.resourcemanager.ResourceManager: Transitioned to standby state
2015-04-10 19:30:20,739 INFO org.apache.hadoop.yarn.server.resourcemanager.ResourceManager: SHUTDOWN_MSG: 
/************************************************************
SHUTDOWN_MSG: Shutting down ResourceManager at k08n41s01/10.111.8.41
************************************************************/
